<?xml version="1.0" ?>
<robot name="iiwa7">
<link name="base_link">
  <inertial>
    <origin rpy="0 0 0" xyz="-0.01283618494463161 4.904567390585061e-08 0.07010682239932087"/>
    <mass value="30.324767682917948"/>
    <inertia ixx="0.111667" ixy="0.0" ixz="0.004812" iyy="0.139457" iyz="-0.0" izz="0.133156"/>
  </inertial>
  <visual>
    <origin rpy="0 0 0" xyz="0 0 0"/>
    <geometry>
      <mesh filename="package://fusion2urdf/lbr_description/meshes/iiwa7/base_link_m-binary.stl"/>
    </geometry>
    <material name="silver">
      <color rgba="1 0 0 1"/>
    </material>
  </visual>
  <collision>
    <origin rpy="0 0 0" xyz="0 0 0"/>
    <geometry>
      <mesh filename="package://fusion2urdf/lbr_description/meshes/iiwa7/base_link_m-binary.stl"/>
    </geometry>
  </collision>
</link>
<link name="link_1_1">
  <inertial>
    <origin rpy="0 0 0" xyz="4.9980243666546455e-08 -0.0347335291089292 0.12351608478142942"/>
    <mass value="21.213926420791886"/>
    <inertia ixx="0.134131" ixy="-0.0" ixz="0.0" iyy="0.127957" iyz="0.023881" izz="0.047328"/>
  </inertial>
  <visual>
    <origin rpy="0 0 0" xyz="-0.0 0.0 -0.1475"/>
    <geometry>
      <mesh filename="package://fusion2urdf/lbr_description/meshes/iiwa7/link_1_1_m-binary.stl"/>
    </geometry>
    <material name="silver">
      <color rgba="1 0 0 1"/>
    </material>
  </visual>
  <collision>
    <origin rpy="0 0 0" xyz="-0.0 0.0 -0.1475"/>
    <geometry>
      <mesh filename="package://fusion2urdf/lbr_description/meshes/iiwa7/link_1_1_m-binary.stl"/>
    </geometry>
  </collision>
</link>
<link name="link_2_1">
  <inertial>
    <origin rpy="0 0 0" xyz="4.0558428502019873e-08 0.04491581578298656 0.06732515284873997"/>
    <mass value="21.39756651772542"/>
    <inertia ixx="0.133839" ixy="-0.0" ixz="0.0" iyy="0.12753" iyz="0.022271" izz="0.047853"/>
  </inertial>
  <visual>
    <origin rpy="0 0 0" xyz="0.0 0.0105 -0.3405"/>
    <geometry>
      <mesh filename="package://fusion2urdf/lbr_description/meshes/iiwa7/link_2_1_m-binary.stl"/>
    </geometry>
    <material name="silver">
      <color rgba="1 0 0 1"/>
    </material>
  </visual>
  <collision>
    <origin rpy="0 0 0" xyz="0.0 0.0105 -0.3405"/>
    <geometry>
      <mesh filename="package://fusion2urdf/lbr_description/meshes/iiwa7/link_2_1_m-binary.stl"/>
    </geometry>
  </collision>
</link>
<link name="link_3_1">
  <inertial>
    <origin rpy="0 0 0" xyz="-5.881068064938613e-09 0.02956361869175564 0.1365034185434154"/>
    <mass value="24.923667110884463"/>
    <inertia ixx="0.196866" ixy="-0.0" ixz="0.0" iyy="0.186889" iyz="-0.038259" izz="0.059722"/>
  </inertial>
  <visual>
    <origin rpy="0 0 0" xyz="0.0 0.0 -0.515"/>
    <geometry>
      <mesh filename="package://fusion2urdf/lbr_description/meshes/iiwa7/link_3_1_m-binary.stl"/>
    </geometry>
    <material name="silver">
      <color rgba="1 0 0 1"/>
    </material>
  </visual>
  <collision>
    <origin rpy="0 0 0" xyz="0.0 0.0 -0.515"/>
    <geometry>
      <mesh filename="package://fusion2urdf/lbr_description/meshes/iiwa7/link_3_1_m-binary.stl"/>
    </geometry>
  </collision>
</link>
<link name="link_4_1">
  <inertial>
    <origin rpy="0 0 0" xyz="-4.1344813497116265e-08 -0.044916218629510306 0.06732501840381"/>
    <mass value="21.39755453189086"/>
    <inertia ixx="0.13383" ixy="0.0" ixz="-0.0" iyy="0.127527" iyz="-0.022269" izz="0.047848"/>
  </inertial>
  <visual>
    <origin rpy="0 0 0" xyz="0.0 -0.0105 -0.7405"/>
    <geometry>
      <mesh filename="package://fusion2urdf/lbr_description/meshes/iiwa7/link_4_1_m-binary.stl"/>
    </geometry>
    <material name="silver">
      <color rgba="1 0 0 1"/>
    </material>
  </visual>
  <collision>
    <origin rpy="0 0 0" xyz="0.0 -0.0105 -0.7405"/>
    <geometry>
      <mesh filename="package://fusion2urdf/lbr_description/meshes/iiwa7/link_4_1_m-binary.stl"/>
    </geometry>
  </collision>
</link>
<link name="link_5_1">
  <inertial>
    <origin rpy="0 0 0" xyz="2.416002990197734e-08 -0.021386601078580914 0.085468591256322"/>
    <mass value="13.296700832855965"/>
    <inertia ixx="0.079123" ixy="-0.0" ixz="-0.0" iyy="0.068318" iyz="0.024261" izz="0.035085"/>
  </inertial>
  <visual>
    <origin rpy="0 0 0" xyz="0.0 0.0 -0.915"/>
    <geometry>
      <mesh filename="package://fusion2urdf/lbr_description/meshes/iiwa7/link_5_1_m-binary.stl"/>
    </geometry>
    <material name="silver">
      <color rgba="1 0 0 1"/>
    </material>
  </visual>
  <collision>
    <origin rpy="0 0 0" xyz="0.0 0.0 -0.915"/>
    <geometry>
      <mesh filename="package://fusion2urdf/lbr_description/meshes/iiwa7/link_5_1_m-binary.stl"/>
    </geometry>
  </collision>
</link>
<link name="link_6_1">
  <inertial>
    <origin rpy="0 0 0" xyz="-9.07120004240837e-08 0.0709871260349443 0.002115721730276743"/>
    <mass value="14.421451173118493"/>
    <inertia ixx="0.040001" ixy="-0.0" ixz="-0.0" iyy="0.038461" iyz="0.00196" izz="0.027816"/>
  </inertial>
  <visual>
    <origin rpy="0 0 0" xyz="0.0 0.0707 -1.1405"/>
    <geometry>
      <mesh filename="package://fusion2urdf/lbr_description/meshes/iiwa7/link_6_1_m-binary.stl"/>
    </geometry>
    <material name="silver">
      <color rgba="1 0 0 1"/>
    </material>
  </visual>
  <collision>
    <origin rpy="0 0 0" xyz="0.0 0.0707 -1.1405"/>
    <geometry>
      <mesh filename="package://fusion2urdf/lbr_description/meshes/iiwa7/link_6_1_m-binary.stl"/>
    </geometry>
  </collision>
</link>
<link name="link_7_1">
  <inertial>
    <origin rpy="0 0 0" xyz="4.535378460217862e-06 -1.7615872956281168e-08 0.009883270430701696"/>
    <mass value="2.113113203151399"/>
    <inertia ixx="0.001557" ixy="-0.0" ixz="-0.0" iyy="0.00153" iyz="0.0" izz="0.002532"/>
  </inertial>
  <visual>
    <origin rpy="0 0 0" xyz="0.0 0.0002 -1.2314"/>
    <geometry>
      <mesh filename="package://fusion2urdf/lbr_description/meshes/iiwa7/link_7_1_m-binary.stl"/>
    </geometry>
    <material name="silver">
      <color rgba="1 0 0 1"/>
    </material>
  </visual>
  <collision>
    <origin rpy="0 0 0" xyz="0.0 0.0002 -1.2314"/>
    <geometry>
      <mesh filename="package://fusion2urdf/lbr_description/meshes/iiwa7/link_7_1_m-binary.stl"/>
    </geometry>
  </collision>
</link>
<joint name="A1" type="revolute">
  <origin rpy="0 0 0" xyz="0.0 0.0 0.1475"/>
  <parent link="base_link"/>
  <child link="link_1_1"/>
  <axis xyz="0.0 0.0 0.01"/>
  <limit effort="100" lower="-2.96706" upper="2.96706" velocity="1.71042267"/>
</joint>
<transmission name="A1_tran">
  <type>transmission_interface/SimpleTransmission</type>
  <joint name="A1">
    <hardwareInterface>PositionJointInterface</hardwareInterface>
  </joint>
  <actuator name="A1_actr">
    <hardwareInterface>PositionJointInterface</hardwareInterface>
    <mechanicalReduction>1</mechanicalReduction>
  </actuator>
</transmission>
<joint name="A2" type="revolute">
  <origin rpy="0 0 0" xyz="-0.0 -0.0105 0.193"/>
  <parent link="link_1_1"/>
  <child link="link_2_1"/>
  <axis xyz="0.0 0.01 0.0"/>
  <limit effort="100" lower="-2.094395" upper="2.094395" velocity="1.71042267"/>
</joint>
<transmission name="A2_tran">
  <type>transmission_interface/SimpleTransmission</type>
  <joint name="A2">
    <hardwareInterface>PositionJointInterface</hardwareInterface>
  </joint>
  <actuator name="A2_actr">
    <hardwareInterface>PositionJointInterface</hardwareInterface>
    <mechanicalReduction>1</mechanicalReduction>
  </actuator>
</transmission>
<joint name="A3" type="revolute">
  <origin rpy="0 0 0" xyz="0.0 0.0105 0.1745"/>
  <parent link="link_2_1"/>
  <child link="link_3_1"/>
  <axis xyz="0.0 0.0 0.01"/>
  <limit effort="100" lower="-2.96706" upper="2.96706" velocity="1.74532925"/>
</joint>
<transmission name="A3_tran">
  <type>transmission_interface/SimpleTransmission</type>
  <joint name="A3">
    <hardwareInterface>PositionJointInterface</hardwareInterface>
  </joint>
  <actuator name="A3_actr">
    <hardwareInterface>PositionJointInterface</hardwareInterface>
    <mechanicalReduction>1</mechanicalReduction>
  </actuator>
</transmission>
<joint name="A4" type="revolute">
  <origin rpy="0 0 0" xyz="0.0 0.0105 0.2255"/>
  <parent link="link_3_1"/>
  <child link="link_4_1"/>
  <axis xyz="0.0 -0.01 0.0"/>
  <limit effort="100" lower="-2.094395" upper="2.094395" velocity="2.26892803"/>
</joint>
<transmission name="A4_tran">
  <type>transmission_interface/SimpleTransmission</type>
  <joint name="A4">
    <hardwareInterface>PositionJointInterface</hardwareInterface>
  </joint>
  <actuator name="A4_actr">
    <hardwareInterface>PositionJointInterface</hardwareInterface>
    <mechanicalReduction>1</mechanicalReduction>
  </actuator>
</transmission>
<joint name="A5" type="revolute">
  <origin rpy="0 0 0" xyz="0.0 -0.0105 0.1745"/>
  <parent link="link_4_1"/>
  <child link="link_5_1"/>
  <axis xyz="0.0 0.0 0.01"/>
  <limit effort="100" lower="-2.96706" upper="2.96706" velocity="2.44346095"/>
</joint>
<transmission name="A5_tran">
  <type>transmission_interface/SimpleTransmission</type>
  <joint name="A5">
    <hardwareInterface>PositionJointInterface</hardwareInterface>
  </joint>
  <actuator name="A5_actr">
    <hardwareInterface>PositionJointInterface</hardwareInterface>
    <mechanicalReduction>1</mechanicalReduction>
  </actuator>
</transmission>
<joint name="A6" type="revolute">
  <origin rpy="0 0 0" xyz="0.0 -0.0707 0.2255"/>
  <parent link="link_5_1"/>
  <child link="link_6_1"/>
  <axis xyz="0.0 0.01 0.0"/>
  <limit effort="100" lower="-2.094395" upper="2.094395" velocity="3.14159265"/>
</joint>
<transmission name="A6_tran">
  <type>transmission_interface/SimpleTransmission</type>
  <joint name="A6">
    <hardwareInterface>PositionJointInterface</hardwareInterface>
  </joint>
  <actuator name="A6_actr">
    <hardwareInterface>PositionJointInterface</hardwareInterface>
    <mechanicalReduction>1</mechanicalReduction>
  </actuator>
</transmission>
<joint name="A7" type="revolute">
  <origin rpy="0 0 0" xyz="0.0 0.0705 0.0909"/>
  <parent link="link_6_1"/>
  <child link="link_7_1"/>
  <axis xyz="0.0 0.0 0.01"/>
  <limit effort="100" lower="-3.054326" upper="3.054326" velocity="3.14159265"/>
</joint>
<transmission name="A7_tran">
  <type>transmission_interface/SimpleTransmission</type>
  <joint name="A7">
    <hardwareInterface>PositionJointInterface</hardwareInterface>
  </joint>
  <actuator name="A7_actr">
    <hardwareInterface>PositionJointInterface</hardwareInterface>
    <mechanicalReduction>1</mechanicalReduction>
  </actuator>
</transmission>
<gazebo>
  <plugin filename="libgazebo_ros_control.so" name="control"/>
</gazebo>
</robot>
