<?xml version="1.0"?>

<robot xmlns:xacro="http://www.ros.org/wiki/xacro">

    <!-- include gazebo specifications -->
    <xacro:include filename="$(find lbr_description)/urdf/iiwa.gazebo.xacro"/>

    <!-- include transmission for ros_control -->
    <xacro:include filename="$(find lbr_description)/urdf/lbr.transmission.xacro"/>

    <!-- include materials -->
    <xacro:include filename="$(find lbr_description)/urdf/lbr.materials.xacro"/>

    <!-- some constants -->
    <xacro:property name="PI" value="3.1415926535897931"/>
    <xacro:property name="safety_controller_k_pos" value="100"/>
    <xacro:property name="safety_controller_k_vel" value="2"/> 
    <xacro:property name="joint_damping" value="10.0"/>
    <xacro:property name="joint_friction" value="0.1"/>
    <xacro:property name="max_effort" value="300"/>
    <xacro:property name="max_velocity" value="10"/>

    <!-- robot as extracted via https://github.com/syuntoku14/fusion2urdf -->
    <xacro:macro name="iiwa7" params="hardware_interface *origin parent robot_name">

        <!--joint between {parent} and link_0-->
        <joint name="${parent}_${robot_name}_joint" type="fixed">
            <xacro:insert_block name="origin"/>
            <parent link="${parent}"/>
            <child link="${robot_name}_link_0"/>
        </joint>

        <link name="${robot_name}_link_0">
            <inertial>
            <origin rpy="0 0 0" xyz="-0.01283618494463161 4.904567390585061e-08 0.07010682239932087"/>
            <mass value="30.324767682917948"/>
            <inertia ixx="0.111667" ixy="0.0" ixz="0.004812" iyy="0.139457" iyz="-0.0" izz="0.133156"/>
            </inertial>
            <visual>
            <origin rpy="0 0 0" xyz="0 0 0"/>
            <geometry>
                <mesh filename="package://lbr_description/meshes/iiwa7/visual/link_0.stl"/>
            </geometry>
            <material name="silver"/>
            </visual>
            <collision>
            <origin rpy="0 0 0" xyz="0 0 0"/>
            <geometry>
                <mesh filename="package://lbr_description/meshes/iiwa7/collision/link_0.stl"/>
            </geometry>
            </collision>
        </link>

        <joint name="${robot_name}_joint_1" type="revolute">
            <origin rpy="0 0 0" xyz="0.0 0.0 0.1475"/>
            <parent link="${robot_name}_link_0"/>
            <child link="${robot_name}_link_1"/>
            <axis xyz="0.0 0.0 0.01"/>
            <limit effort="${max_effort}" lower="${-170 * PI / 180}" upper="${170 * PI / 180}" velocity="${max_velocity}"/>
            <safety_controller 
                soft_lower_limit="${-168 * PI / 180}"
                soft_upper_limit="${168 * PI / 180}"
                k_position="${safety_controller_k_pos}"
                k_velocity="${safety_controller_k_vel}"
            /> 
            <dynamics damping="${joint_damping}" friction="${joint_friction}"/>
        </joint>

        <link name="${robot_name}_link_1">
            <inertial>
            <origin rpy="0 0 0" xyz="4.9980243666546455e-08 -0.0347335291089292 0.12351608478142942"/>
            <mass value="21.213926420791886"/>
            <inertia ixx="0.134131" ixy="-0.0" ixz="0.0" iyy="0.127957" iyz="0.023881" izz="0.047328"/>
            </inertial>
            <visual>
            <origin rpy="0 0 0" xyz="-0.0 0.0 -0.1475"/>
            <geometry>
                <mesh filename="package://lbr_description/meshes/iiwa7/visual/link_1.stl"/>
            </geometry>
            <material name="orange"/>
            </visual>
            <collision>
            <origin rpy="0 0 0" xyz="-0.0 0.0 -0.1475"/>
            <geometry>
                <mesh filename="package://lbr_description/meshes/iiwa7/collision/link_1.stl"/>
            </geometry>
            </collision>
        </link>

        <joint name="${robot_name}_joint_2" type="revolute">
            <origin rpy="0 0 0" xyz="-0.0 -0.0105 0.193"/>
            <parent link="${robot_name}_link_1"/>
            <child link="${robot_name}_link_2"/>
            <axis xyz="0.0 0.01 0.0"/>
            <limit effort="${max_effort}" lower="${-120 * PI / 180}" upper="${120 * PI / 180}" velocity="${max_velocity}"/>
            <safety_controller 
                soft_lower_limit="${-118 * PI / 180}"
                soft_upper_limit="${118 * PI / 180}"
                k_position="${safety_controller_k_pos}"
                k_velocity="${safety_controller_k_vel}"
            /> 
            <dynamics damping="${joint_damping}" friction="${joint_friction}"/>
        </joint>

        <link name="${robot_name}_link_2">
            <inertial>
            <origin rpy="0 0 0" xyz="4.0558428502019873e-08 0.04491581578298656 0.06732515284873997"/>
            <mass value="21.39756651772542"/>
            <inertia ixx="0.133839" ixy="-0.0" ixz="0.0" iyy="0.12753" iyz="0.022271" izz="0.047853"/>
            </inertial>
            <visual>
            <origin rpy="0 0 0" xyz="0.0 0.0105 -0.3405"/>
            <geometry>
                <mesh filename="package://lbr_description/meshes/iiwa7/visual/link_2.stl"/>
            </geometry>
            <material name="orange"/>
            </visual>
            <collision>
            <origin rpy="0 0 0" xyz="0.0 0.0105 -0.3405"/>
            <geometry>
                <mesh filename="package://lbr_description/meshes/iiwa7/collision/link_2.stl"/>
            </geometry>
            </collision>
        </link>

        <joint name="${robot_name}_joint_3" type="revolute">
            <origin rpy="0 0 0" xyz="0.0 0.0105 0.1745"/>
            <parent link="${robot_name}_link_2"/>
            <child link="${robot_name}_link_3"/>
            <axis xyz="0.0 0.0 0.01"/>
            <limit effort="${max_effort}" lower="${-170 * PI / 180}" upper="${170 * PI / 180}" velocity="${max_velocity}"/>
            <safety_controller 
                soft_lower_limit="${-168 * PI / 180}"
                soft_upper_limit="${168 * PI / 180}"
                k_position="${safety_controller_k_pos}"
                k_velocity="${safety_controller_k_vel}"
            /> 
            <dynamics damping="${joint_damping}" friction="${joint_friction}"/>
        </joint>

        <link name="${robot_name}_link_3">
            <inertial>
            <origin rpy="0 0 0" xyz="-5.881068064938613e-09 0.02956361869175564 0.1365034185434154"/>
            <mass value="24.923667110884463"/>
            <inertia ixx="0.196866" ixy="-0.0" ixz="0.0" iyy="0.186889" iyz="-0.038259" izz="0.059722"/>
            </inertial>
            <visual>
            <origin rpy="0 0 0" xyz="0.0 0.0 -0.515"/>
            <geometry>
                <mesh filename="package://lbr_description/meshes/iiwa7/visual/link_3.stl"/>
            </geometry>
            <material name="orange"/>
            </visual>
            <collision>
            <origin rpy="0 0 0" xyz="0.0 0.0 -0.515"/>
            <geometry>
                <mesh filename="package://lbr_description/meshes/iiwa7/collision/link_3.stl"/>
            </geometry>
            </collision>
        </link>

        <joint name="${robot_name}_joint_4" type="revolute">
            <origin rpy="0 0 0" xyz="0.0 0.0105 0.2255"/>
            <parent link="${robot_name}_link_3"/>
            <child link="${robot_name}_link_4"/>
            <axis xyz="0.0 -0.01 0.0"/>
            <limit effort="${max_effort}" lower="${-120 * PI / 180}" upper="${120 * PI / 180}" velocity="${max_velocity}"/>
            <safety_controller 
                soft_lower_limit="${-118 * PI / 180}"
                soft_upper_limit="${118 * PI / 180}"
                k_position="${safety_controller_k_pos}"
                k_velocity="${safety_controller_k_vel}"
            /> 
            <dynamics damping="${joint_damping}" friction="${joint_friction}"/>
        </joint>

        <link name="${robot_name}_link_4">
            <inertial>
            <origin rpy="0 0 0" xyz="-4.1344813497116265e-08 -0.044916218629510306 0.06732501840381"/>
            <mass value="21.39755453189086"/>
            <inertia ixx="0.13383" ixy="0.0" ixz="-0.0" iyy="0.127527" iyz="-0.022269" izz="0.047848"/>
            </inertial>
            <visual>
            <origin rpy="0 0 0" xyz="0.0 -0.0105 -0.7405"/>
            <geometry>
                <mesh filename="package://lbr_description/meshes/iiwa7/visual/link_4.stl"/>
            </geometry>
            <material name="orange"/>
            </visual>
            <collision>
            <origin rpy="0 0 0" xyz="0.0 -0.0105 -0.7405"/>
            <geometry>
                <mesh filename="package://lbr_description/meshes/iiwa7/collision/link_4.stl"/>
            </geometry>
            </collision>
        </link>

        <joint name="${robot_name}_joint_5" type="revolute">
            <origin rpy="0 0 0" xyz="0.0 -0.0105 0.1745"/>
            <parent link="${robot_name}_link_4"/>
            <child link="${robot_name}_link_5"/>
            <axis xyz="0.0 0.0 0.01"/>
            <limit effort="${max_effort}" lower="${-170 * PI / 180}" upper="${170 * PI / 180}" velocity="${max_velocity}"/>
            <safety_controller 
                soft_lower_limit="${-168 * PI / 180}"
                soft_upper_limit="${168 * PI / 180}"
                k_position="${safety_controller_k_pos}"
                k_velocity="${safety_controller_k_vel}"
            /> 
            <dynamics damping="${joint_damping}" friction="${joint_friction}"/>
        </joint>

        <link name="${robot_name}_link_5">
            <inertial>
            <origin rpy="0 0 0" xyz="2.416002990197734e-08 -0.021386601078580914 0.085468591256322"/>
            <mass value="13.296700832855965"/>
            <inertia ixx="0.079123" ixy="-0.0" ixz="-0.0" iyy="0.068318" iyz="0.024261" izz="0.035085"/>
            </inertial>
            <visual>
            <origin rpy="0 0 0" xyz="0.0 0.0 -0.915"/>
            <geometry>
                <mesh filename="package://lbr_description/meshes/iiwa7/visual/link_5.stl"/>
            </geometry>
            <material name="orange"/>
            </visual>
            <collision>
            <origin rpy="0 0 0" xyz="0.0 0.0 -0.915"/>
            <geometry>
                <mesh filename="package://lbr_description/meshes/iiwa7/collision/link_5.stl"/>
            </geometry>
            </collision>
        </link>

        <joint name="${robot_name}_joint_6" type="revolute">
            <origin rpy="0 0 0" xyz="0.0 -0.0707 0.2255"/>
            <parent link="${robot_name}_link_5"/>
            <child link="${robot_name}_link_6"/>
            <axis xyz="0.0 0.01 0.0"/>
            <limit effort="${max_effort}" lower="${-120 * PI / 180}" upper="${120 * PI / 180}" velocity="${max_velocity}"/>
            <safety_controller 
                soft_lower_limit="${-118 * PI / 180}"
                soft_upper_limit="${118 * PI / 180}"
                k_position="${safety_controller_k_pos}"
                k_velocity="${safety_controller_k_vel}"
            /> 
            <dynamics damping="${joint_damping}" friction="${joint_friction}"/>
        </joint>

        <link name="${robot_name}_link_6">
            <inertial>
            <origin rpy="0 0 0" xyz="-9.07120004240837e-08 0.0709871260349443 0.002115721730276743"/>
            <mass value="14.421451173118493"/>
            <inertia ixx="0.040001" ixy="-0.0" ixz="-0.0" iyy="0.038461" iyz="0.00196" izz="0.027816"/>
            </inertial>
            <visual>
            <origin rpy="0 0 0" xyz="0.0 0.0707 -1.1405"/>
            <geometry>
                <mesh filename="package://lbr_description/meshes/iiwa7/visual/link_6.stl"/>
            </geometry>
            <material name="orange"/>
            </visual>
            <collision>
            <origin rpy="0 0 0" xyz="0.0 0.0707 -1.1405"/>
            <geometry>
                <mesh filename="package://lbr_description/meshes/iiwa7/collision/link_6.stl"/>
            </geometry>
            </collision>
        </link>


        <joint name="${robot_name}_joint_7" type="revolute">
            <origin rpy="0 0 0" xyz="0.0 0.0705 0.0909"/>
            <parent link="${robot_name}_link_6"/>
            <child link="${robot_name}_link_7"/>
            <axis xyz="0.0 0.0 0.01"/>
            <limit effort="${max_effort}" lower="${-175 * PI / 180}" upper="${175 * PI / 180}" velocity="${max_velocity}"/>
            <safety_controller 
                soft_lower_limit="${-173 * PI / 180}"
                soft_upper_limit="${173 * PI / 180}"
                k_position="${safety_controller_k_pos}"
                k_velocity="${safety_controller_k_vel}"
            /> 
            <dynamics damping="${joint_damping}" friction="${joint_friction}"/>
        </joint>

        <link name="${robot_name}_link_7">
            <inertial>
            <origin rpy="0 0 0" xyz="4.535378460217862e-06 -1.7615872956281168e-08 0.009883270430701696"/>
            <mass value="2.113113203151399"/>
            <inertia ixx="0.001557" ixy="-0.0" ixz="-0.0" iyy="0.00153" iyz="0.0" izz="0.002532"/>
            </inertial>
            <visual>
            <origin rpy="0 0 0" xyz="0.0 0.0002 -1.2314"/>
            <geometry>
                <mesh filename="package://lbr_description/meshes/iiwa7/visual/link_7.stl"/>
            </geometry>
            <material name="silver"/>
            </visual>
            <collision>
            <origin rpy="0 0 0" xyz="0.0 0.0002 -1.2314"/>
            <geometry>
                <mesh filename="package://lbr_description/meshes/iiwa7/collision/link_7.stl"/>
            </geometry>
            </collision>
        </link>    

        <joint name="${robot_name}_joint_ee" type="fixed">
            <parent link="${robot_name}_link_7"/>
            <child link="${robot_name}_link_ee"/>
            <origin xyz="0 0 0.035" rpy="0 0 0"/>
        </joint>
        
        <link name="${robot_name}_link_ee">
        </link>

        <!-- extensions -->
        <xacro:iiwa_gazebo robot_name="${robot_name}"/>
        <xacro:lbr_transmission hardware_interface="${hardware_interface}" robot_name="${robot_name}"/>
    </xacro:macro>

</robot>
