<?xml version="1.0" ?>
<robot name="iiwa14">
<link name="world"/>
<link name="base_link">
  <inertial>
    <origin rpy="0 0 0" xyz="-0.0128215344957798 -7.86364415362405e-08 0.07150661827888387"/>
    <mass value="42.98914417363736"/>
    <inertia ixx="0.190401" ixy="0.0" ixz="0.005312" iyy="0.242047" iyz="0.0" izz="0.262814"/>
  </inertial>
  <visual>
    <origin rpy="0 0 0" xyz="0 0 0"/>
    <geometry>
      <mesh filename="package://fusion2urdf/lbr_description/meshes/iiwa14/base_link.stl"/>
    </geometry>
    <material name="silver">
      <color rgba="1 0 0 1"/>
    </material>
  </visual>
  <collision>
    <origin rpy="0 0 0" xyz="0 0 0"/>
    <geometry>
      <mesh filename="package://fusion2urdf/lbr_description/meshes/iiwa14/base_link.stl"/>
    </geometry>
  </collision>
</link>
<link name="link_1">
  <inertial>
    <origin rpy="0 0 0" xyz="9.307232415315581e-08 -0.03379543155079102 0.13240370669453902"/>
    <mass value="32.252499792432545"/>
    <inertia ixx="0.258906" ixy="-0.0" ixz="-0.0" iyy="0.261201" iyz="0.038666" izz="0.096765"/>
  </inertial>
  <visual>
    <origin rpy="0 0 0" xyz="-0.0 0.0 -0.1475"/>
    <geometry>
      <mesh filename="package://fusion2urdf/lbr_description/meshes/iiwa14/link_1.stl"/>
    </geometry>
    <material name="silver">
      <color rgba="1 0 0 1"/>
    </material>
  </visual>
  <collision>
    <origin rpy="0 0 0" xyz="-0.0 0.0 -0.1475"/>
    <geometry>
      <mesh filename="package://fusion2urdf/lbr_description/meshes/iiwa14/link_1.stl"/>
    </geometry>
  </collision>
</link>
<link name="link_2">
  <inertial>
    <origin rpy="0 0 0" xyz="0.00015188022518878674 0.051987109728758904 0.05880129877994178"/>
    <mass value="31.020446759849573"/>
    <inertia ixx="0.240168" ixy="-0.000179" ixz="0.000259" iyy="0.238795" iyz="0.038362" izz="0.086485"/>
  </inertial>
  <visual>
    <origin rpy="0 0 0" xyz="-0.0 0.01 -0.36"/>
    <geometry>
      <mesh filename="package://fusion2urdf/lbr_description/meshes/iiwa14/link_2.stl"/>
    </geometry>
    <material name="silver">
      <color rgba="1 0 0 1"/>
    </material>
  </visual>
  <collision>
    <origin rpy="0 0 0" xyz="-0.0 0.01 -0.36"/>
    <geometry>
      <mesh filename="package://fusion2urdf/lbr_description/meshes/iiwa14/link_2.stl"/>
    </geometry>
  </collision>
</link>
<link name="link_3">
  <inertial>
    <origin rpy="0 0 0" xyz="-5.974614313346012e-09 0.029563618732667742 0.13650341869763982"/>
    <mass value="24.923667076480577"/>
    <inertia ixx="0.196866" ixy="-0.0" ixz="0.0" iyy="0.186889" iyz="-0.038259" izz="0.059722"/>
  </inertial>
  <visual>
    <origin rpy="0 0 0" xyz="-0.0 0.0 -0.5545"/>
    <geometry>
      <mesh filename="package://fusion2urdf/lbr_description/meshes/iiwa14/link_3.stl"/>
    </geometry>
    <material name="silver">
      <color rgba="1 0 0 1"/>
    </material>
  </visual>
  <collision>
    <origin rpy="0 0 0" xyz="-0.0 0.0 -0.5545"/>
    <geometry>
      <mesh filename="package://fusion2urdf/lbr_description/meshes/iiwa14/link_3.stl"/>
    </geometry>
  </collision>
</link>
<link name="link_4">
  <inertial>
    <origin rpy="0 0 0" xyz="-2.09625967727708e-08 -0.04476439079596513 0.06741903952954653"/>
    <mass value="21.50439908415142"/>
    <inertia ixx="0.135049" ixy="-0.0" ixz="-0.0" iyy="0.128699" iyz="-0.022352" izz="0.048185"/>
  </inertial>
  <visual>
    <origin rpy="0 0 0" xyz="0.0 -0.0105 -0.78"/>
    <geometry>
      <mesh filename="package://fusion2urdf/lbr_description/meshes/iiwa14/link_4.stl"/>
    </geometry>
    <material name="silver">
      <color rgba="1 0 0 1"/>
    </material>
  </visual>
  <collision>
    <origin rpy="0 0 0" xyz="0.0 -0.0105 -0.78"/>
    <geometry>
      <mesh filename="package://fusion2urdf/lbr_description/meshes/iiwa14/link_4.stl"/>
    </geometry>
  </collision>
</link>
<link name="link_5">
  <inertial>
    <origin rpy="0 0 0" xyz="-0.00012008657208039079 -0.021390023245727908 0.0854754261653966"/>
    <mass value="13.29457566606638"/>
    <inertia ixx="0.079116" ixy="1.2e-05" ixz="-6e-06" iyy="0.06831" iyz="0.024259" izz="0.035078"/>
  </inertial>
  <visual>
    <origin rpy="0 0 0" xyz="-0.0 0.0 -0.9545"/>
    <geometry>
      <mesh filename="package://fusion2urdf/lbr_description/meshes/iiwa14/link_5.stl"/>
    </geometry>
    <material name="silver">
      <color rgba="1 0 0 1"/>
    </material>
  </visual>
  <collision>
    <origin rpy="0 0 0" xyz="-0.0 0.0 -0.9545"/>
    <geometry>
      <mesh filename="package://fusion2urdf/lbr_description/meshes/iiwa14/link_5.stl"/>
    </geometry>
  </collision>
</link>
<link name="link_6">
  <inertial>
    <origin rpy="0 0 0" xyz="-6.000032555678588e-08 0.07103825551434698 0.000565530522845803"/>
    <mass value="14.198362583652283"/>
    <inertia ixx="0.038424" ixy="-0.0" ixz="-0.0" iyy="0.036784" iyz="0.001919" izz="0.027998"/>
  </inertial>
  <visual>
    <origin rpy="0 0 0" xyz="0.0 0.0707 -1.18"/>
    <geometry>
      <mesh filename="package://fusion2urdf/lbr_description/meshes/iiwa14/link_6.stl"/>
    </geometry>
    <material name="silver">
      <color rgba="1 0 0 1"/>
    </material>
  </visual>
  <collision>
    <origin rpy="0 0 0" xyz="0.0 0.0707 -1.18"/>
    <geometry>
      <mesh filename="package://fusion2urdf/lbr_description/meshes/iiwa14/link_6.stl"/>
    </geometry>
  </collision>
</link>
<link name="link_7">
  <inertial>
    <origin rpy="0 0 0" xyz="3.963019849314055e-06 -1.5392768444664745e-08 0.027186686478491096"/>
    <mass value="2.4182992945540933"/>
    <inertia ixx="0.001719" ixy="-0.0" ixz="-0.0" iyy="0.001692" iyz="0.0" izz="0.002627"/>
  </inertial>
  <visual>
    <origin rpy="0 0 0" xyz="0.0 0.0 -1.2511"/>
    <geometry>
      <mesh filename="package://fusion2urdf/lbr_description/meshes/iiwa14/link_7.stl"/>
    </geometry>
    <material name="silver">
      <color rgba="1 0 0 1"/>
    </material>
  </visual>
  <collision>
    <origin rpy="0 0 0" xyz="0.0 0.0 -1.2511"/>
    <geometry>
      <mesh filename="package://fusion2urdf/lbr_description/meshes/iiwa14/link_7.stl"/>
    </geometry>
  </collision>
</link>
<joint name="world_iiwa7_joint" type="fixed"> <!-- joint between world and robot -->
  <origin rpy="0 0 0" xyz="0.0 0.0 0.0"/>
  <parent link="world"/>
  <child link="base_link"/>
</joint>
<joint name="A1" type="revolute">
  <origin rpy="0 0 0" xyz="0.0 0.0 0.1475"/>
  <parent link="base_link"/>
  <child link="link_1"/>
  <axis xyz="0.0 0.0 0.01"/>
  <limit effort="100" lower="-2.96706" upper="2.96706" velocity="100"/>
</joint>
<transmission name="A1_tran">
  <type>transmission_interface/SimpleTransmission</type>
  <joint name="A1">
    <hardwareInterface>PositionJointInterface</hardwareInterface>
  </joint>
  <actuator name="A1_actr">
    <hardwareInterface>PositionJointInterface</hardwareInterface>
    <mechanicalReduction>1</mechanicalReduction>
  </actuator>
</transmission>
<joint name="A2" type="revolute">
  <origin rpy="0 0 0" xyz="0.0 -0.01 0.2125"/>
  <parent link="link_1"/>
  <child link="link_2"/>
  <axis xyz="0.0 0.01 0.0"/>
  <limit effort="100" lower="-2.094395" upper="2.094395" velocity="100"/>
</joint>
<transmission name="A2_tran">
  <type>transmission_interface/SimpleTransmission</type>
  <joint name="A2">
    <hardwareInterface>PositionJointInterface</hardwareInterface>
  </joint>
  <actuator name="A2_actr">
    <hardwareInterface>PositionJointInterface</hardwareInterface>
    <mechanicalReduction>1</mechanicalReduction>
  </actuator>
</transmission>
<joint name="A3" type="revolute">
  <origin rpy="0 0 0" xyz="0.0 0.01 0.1945"/>
  <parent link="link_2"/>
  <child link="link_3"/>
  <axis xyz="0.0 0.0 0.01"/>
  <limit effort="100" lower="-2.96706" upper="2.96706" velocity="100"/>
</joint>
<transmission name="A3_tran">
  <type>transmission_interface/SimpleTransmission</type>
  <joint name="A3">
    <hardwareInterface>PositionJointInterface</hardwareInterface>
  </joint>
  <actuator name="A3_actr">
    <hardwareInterface>PositionJointInterface</hardwareInterface>
    <mechanicalReduction>1</mechanicalReduction>
  </actuator>
</transmission>
<joint name="A4" type="revolute">
  <origin rpy="0 0 0" xyz="-0.0 0.0105 0.2255"/>
  <parent link="link_3"/>
  <child link="link_4"/>
  <axis xyz="0.0 -0.01 0.0"/>
  <limit effort="100" lower="-2.094395" upper="2.094395" velocity="100"/>
</joint>
<transmission name="A4_tran">
  <type>transmission_interface/SimpleTransmission</type>
  <joint name="A4">
    <hardwareInterface>PositionJointInterface</hardwareInterface>
  </joint>
  <actuator name="A4_actr">
    <hardwareInterface>PositionJointInterface</hardwareInterface>
    <mechanicalReduction>1</mechanicalReduction>
  </actuator>
</transmission>
<joint name="A5" type="revolute">
  <origin rpy="0 0 0" xyz="0.0 -0.0105 0.1745"/>
  <parent link="link_4"/>
  <child link="link_5"/>
  <axis xyz="0.0 0.0 0.01"/>
  <limit effort="100" lower="-2.96706" upper="2.96706" velocity="100"/>
</joint>
<transmission name="A5_tran">
  <type>transmission_interface/SimpleTransmission</type>
  <joint name="A5">
    <hardwareInterface>PositionJointInterface</hardwareInterface>
  </joint>
  <actuator name="A5_actr">
    <hardwareInterface>PositionJointInterface</hardwareInterface>
    <mechanicalReduction>1</mechanicalReduction>
  </actuator>
</transmission>
<joint name="A6" type="revolute">
  <origin rpy="0 0 0" xyz="-0.0 -0.0707 0.2255"/>
  <parent link="link_5"/>
  <child link="link_6"/>
  <axis xyz="0.0 0.01 0.0"/>
  <limit effort="100" lower="-2.094395" upper="2.094395" velocity="100"/>
</joint>
<transmission name="A6_tran">
  <type>transmission_interface/SimpleTransmission</type>
  <joint name="A6">
    <hardwareInterface>PositionJointInterface</hardwareInterface>
  </joint>
  <actuator name="A6_actr">
    <hardwareInterface>PositionJointInterface</hardwareInterface>
    <mechanicalReduction>1</mechanicalReduction>
  </actuator>
</transmission>
<joint name="A7" type="revolute">
  <origin rpy="0 0 0" xyz="0.0 0.0707 0.0711"/>
  <parent link="link_6"/>
  <child link="link_7"/>
  <axis xyz="0.0 0.0 0.01"/>
  <limit effort="100" lower="-3.054326" upper="3.054326" velocity="100"/>
</joint>
<transmission name="A7_tran">
  <type>transmission_interface/SimpleTransmission</type>
  <joint name="A7">
    <hardwareInterface>PositionJointInterface</hardwareInterface>
  </joint>
  <actuator name="A7_actr">
    <hardwareInterface>PositionJointInterface</hardwareInterface>
    <mechanicalReduction>1</mechanicalReduction>
  </actuator>
</transmission>
<gazebo>
  <plugin filename="libgazebo_ros_control.so" name="control"/>
</gazebo>
</robot>
