<?xml version="1.0"?>

<robot xmlns:xacro="http://www.ros.org/wiki/xacro">

    <!-- include gazebo specifications -->
    <xacro:include filename="$(find lbr_description)/urdf/med.gazebo.xacro" />

    <!-- include transmission for ros_control -->
    <xacro:include filename="$(find lbr_description)/urdf/lbr.transmission.xacro" />

    <!-- include materials -->
    <xacro:include filename="$(find lbr_description)/urdf/lbr.materials.xacro" />

    <!-- some constants -->
    <xacro:property name="PI" value="3.1415926535897931" />
    <xacro:property name="safety_controller_k_pos" value="100" />
    <xacro:property name="safety_controller_k_vel" value="2" />
    <xacro:property name="joint_damping" value="10.0" />
    <xacro:property name="joint_friction" value="0.1" />
    <xacro:property name="max_effort" value="300" />
    <xacro:property name="max_velocity" value="10" />

    <!-- robot as extracted via https://github.com/syuntoku14/fusion2urdf -->
    <xacro:macro name="med14" params="hardware_interface *origin parent robot_name">

        <!--joint
        between {parent} and link_0-->
        <joint name="${parent}_${robot_name}_joint" type="fixed">
            <xacro:insert_block name="origin" />
            <parent link="${parent}" />
            <child link="${robot_name}_link_0" />
        </joint>

        <link name="${robot_name}_link_0">
            <inertial>
                <origin rpy="0 0 0" xyz="-0.001864 0.0 0.077517" />
                <mass value="8.146413" />
                <inertia ixx="0.044604" ixy="0.0" ixz="-0.000788" iyy="0.045465" iyz="0.0"
                    izz="0.061904" />
            </inertial>
            <visual>
                <origin rpy="0 0 0" xyz="0 0 0" />
                <geometry>
                    <mesh filename="package://lbr_description/meshes/med14/visual/link_0.dae" />
                </geometry>
            </visual>
            <collision>
                <origin rpy="0 0 0" xyz="0 0 0" />
                <geometry>
                    <mesh filename="package://lbr_description/meshes/med14/collision/link_0.stl" />
                </geometry>
            </collision>
        </link>

        <joint name="${robot_name}_joint_1" type="revolute">
            <origin rpy="0 0 0" xyz="0.0 0.0 0.147" />
            <parent link="${robot_name}_link_0" />
            <child link="${robot_name}_link_1" />
            <axis xyz="0.0 0.0 0.01" />
            <limit effort="${max_effort}" lower="${-170 * PI / 180}" upper="${170 * PI / 180}"
                velocity="${max_velocity}" />
            <safety_controller
                soft_lower_limit="${-168 * PI / 180}"
                soft_upper_limit="${168 * PI / 180}"
                k_position="${safety_controller_k_pos}"
                k_velocity="${safety_controller_k_vel}"
            />
            <dynamics damping="${joint_damping}" friction="${joint_friction}" />
        </joint>

        <link name="${robot_name}_link_1">
            <inertial>
                <origin rpy="0 0 0" xyz="0.0 -0.033795  0.132404" />
                <mass value="5.591419" />
                <inertia ixx="0.044885" ixy="0.0" ixz="0.0" iyy="0.045283" iyz="0.006703"
                    izz="0.016776" />
            </inertial>
            <visual>
                <origin rpy="0 0 0" xyz="0.0 0.0 -0.147" />
                <geometry>
                    <mesh filename="package://lbr_description/meshes/med14/visual/link_1.dae" />
                </geometry>
            </visual>
            <collision>
                <origin rpy="0 0 0" xyz="0.0 0.0 -0.147" />
                <geometry>
                    <mesh filename="package://lbr_description/meshes/med14/collision/link_1.stl" />
                </geometry>
            </collision>
        </link>

        <joint name="${robot_name}_joint_2" type="revolute">
            <origin rpy="0 0 0" xyz="0.0 -0.01 0.2125" />
            <parent link="${robot_name}_link_1" />
            <child link="${robot_name}_link_2" />
            <axis xyz="0.0 0.01 0.0" />
            <limit effort="${max_effort}" lower="${-120 * PI / 180}" upper="${120 * PI / 180}"
                velocity="${max_velocity}" />
            <safety_controller
                soft_lower_limit="${-118 * PI / 180}"
                soft_upper_limit="${118 * PI / 180}"
                k_position="${safety_controller_k_pos}"
                k_velocity="${safety_controller_k_vel}"
            />
            <dynamics damping="${joint_damping}" friction="${joint_friction}" />
        </joint>

        <link name="${robot_name}_link_2">
            <inertial>
                <origin rpy="0 0 0" xyz="0.000136 0.047546 0.076324" />
                <mass value="6.013411" />
                <inertia ixx="0.05833" ixy="-3.5e-05" ixz="5.9e-05" iyy="0.057062" iyz="0.010605"
                    izz="0.017466" />
            </inertial>
            <visual>
                <origin rpy="0 0 0" xyz="0.0 0.01 -0.3595" />
                <geometry>
                    <mesh filename="package://lbr_description/meshes/med14/visual/link_2.dae" />
                </geometry>
            </visual>
            <collision>
                <origin rpy="0 0 0" xyz="0.0 0.01 -0.3595" />
                <geometry>
                    <mesh filename="package://lbr_description/meshes/med14/collision/link_2.stl" />
                </geometry>
            </collision>
        </link>

        <joint name="${robot_name}_joint_3" type="revolute">
            <origin rpy="0 0 0" xyz="-0.0 0.01 0.228" />
            <parent link="${robot_name}_link_2" />
            <child link="${robot_name}_link_3" />
            <axis xyz="0.0 0.0 0.01" />
            <limit effort="${max_effort}" lower="${-170 * PI / 180}" upper="${170 * PI / 180}"
                velocity="${max_velocity}" />
            <safety_controller
                soft_lower_limit="${-168 * PI / 180}"
                soft_upper_limit="${168 * PI / 180}"
                k_position="${safety_controller_k_pos}"
                k_velocity="${safety_controller_k_vel}"
            />
            <dynamics damping="${joint_damping}" friction="${joint_friction}" />
        </joint>

        <link name="${robot_name}_link_3">
            <inertial>
                <origin rpy="0 0 0" xyz="0.0 0.034913 0.123108" />
                <mass value="3.65879" />
                <inertia ixx="0.02296" ixy="0.0" ixz="0.0" iyy="0.021913" iyz="-0.004065"
                    izz="0.00814" />
            </inertial>
            <visual>
                <origin rpy="0 0 0" xyz="0.0 0.0 -0.5875" />
                <geometry>
                    <mesh filename="package://lbr_description/meshes/med14/visual/link_3.dae" />
                </geometry>
            </visual>
            <collision>
                <origin rpy="0 0 0" xyz="0.0 0.0 -0.5875" />
                <geometry>
                    <mesh filename="package://lbr_description/meshes/med14/collision/link_3.stl" />
                </geometry>
            </collision>
        </link>

        <joint name="${robot_name}_joint_4" type="revolute">
            <origin rpy="0 0 0" xyz="0.0 0.0105 0.192" />
            <parent link="${robot_name}_link_3" />
            <child link="${robot_name}_link_4" />
            <axis xyz="0.0 -0.01 0.0" />
            <limit effort="${max_effort}" lower="${-120 * PI / 180}" upper="${120 * PI / 180}"
                velocity="${max_velocity}" />
            <safety_controller
                soft_lower_limit="${-118 * PI / 180}"
                soft_upper_limit="${118 * PI / 180}"
                k_position="${safety_controller_k_pos}"
                k_velocity="${safety_controller_k_vel}"
            />
            <dynamics damping="${joint_damping}" friction="${joint_friction}" />
        </joint>

        <link name="${robot_name}_link_4">
            <inertial>
                <origin rpy="0 0 0" xyz="0.0 -0.039793  0.086944" />
                <mass value="4.358267" />
                <inertia ixx="0.034255" ixy="0.0" ixz="0.0" iyy="0.032512" iyz="-0.006365"
                    izz="0.010444" />
            </inertial>
            <visual>
                <origin rpy="0 0 0" xyz="0.0 -0.0105 -0.7795" />
                <geometry>
                    <mesh filename="package://lbr_description/meshes/med14/visual/link_4.dae" />
                </geometry>
            </visual>
            <collision>
                <origin rpy="0 0 0" xyz="0.0 -0.0105 -0.7795" />
                <geometry>
                    <mesh filename="package://lbr_description/meshes/med14/collision/link_4.stl" />
                </geometry>
            </collision>
        </link>

        <joint name="${robot_name}_joint_5" type="revolute">
            <origin rpy="0 0 0" xyz="0.0 -0.0105 0.2075" />
            <parent link="${robot_name}_link_4" />
            <child link="${robot_name}_link_5" />
            <axis xyz="0.0 0.0 0.01" />
            <limit effort="${max_effort}" lower="${-170 * PI / 180}" upper="${170 * PI / 180}"
                velocity="${max_velocity}" />
            <safety_controller
                soft_lower_limit="${-168 * PI / 180}"
                soft_upper_limit="${168 * PI / 180}"
                k_position="${safety_controller_k_pos}"
                k_velocity="${safety_controller_k_vel}"
            />
            <dynamics damping="${joint_damping}" friction="${joint_friction}" />
        </joint>

        <link name="${robot_name}_link_5">
            <inertial>
                <origin rpy="0 0 0" xyz="0.0 -0.029824  0.076267" />
                <mass value="1.653015" />
                <inertia ixx="0.009172" ixy="0.0" ixz="0.0"
                    iyy="0.007714" iyz="0.003033" izz="0.004159" />
            </inertial>
            <visual>
                <origin rpy="0 0 0" xyz="0.0 0.0 -0.987" />
                <geometry>
                    <mesh filename="package://lbr_description/meshes/med14/visual/link_5.dae" />
                </geometry>
            </visual>
            <collision>
                <origin rpy="0 0 0" xyz="0.0 0.0 -0.987" />
                <geometry>
                    <mesh filename="package://lbr_description/meshes/med14/collision/link_5.stl" />
                </geometry>
            </collision>
        </link>

        <joint name="${robot_name}_joint_6" type="revolute">
            <origin rpy="0 0 0" xyz="0.0 -0.0707 0.1925" />
            <parent link="${robot_name}_link_5" />
            <child link="${robot_name}_link_6" />
            <axis xyz="0.0 0.01 0.0" />
            <limit effort="${max_effort}" lower="${-120 * PI / 180}" upper="${120 * PI / 180}"
                velocity="${max_velocity}" />
            <safety_controller
                soft_lower_limit="${-118 * PI / 180}"
                soft_upper_limit="${118 * PI / 180}"
                k_position="${safety_controller_k_pos}"
                k_velocity="${safety_controller_k_vel}"
            />
            <dynamics damping="${joint_damping}" friction="${joint_friction}" />
        </joint>

        <link name="${robot_name}_link_6">
            <inertial>
                <origin rpy="0 0 0" xyz="-1.000e-06 7.102e-02 4.953e-03" />
                <mass value="2.598211" />
                <inertia ixx="0.00764" ixy="0.0" ixz="0.0" iyy="0.007355" iyz="0.000336"
                    izz="0.005004" />
            </inertial>
            <visual>
                <origin rpy="0 0 0" xyz="0.0 0.0707 -1.1795" />
                <geometry>
                    <mesh filename="package://lbr_description/meshes/med14/visual/link_6.dae" />
                </geometry>
            </visual>
            <collision>
                <origin rpy="0 0 0" xyz="0.0 0.0707 -1.1795" />
                <geometry>
                    <mesh filename="package://lbr_description/meshes/med14/collision/link_6.stl" />
                </geometry>
            </collision>
        </link>

        <joint name="${robot_name}_joint_7" type="revolute">
            <origin rpy="0 0 0" xyz="0.0 0.0707 0.091" />
            <parent link="${robot_name}_link_6" />
            <child link="${robot_name}_link_7" />
            <axis xyz="0.0 0.0 0.01" />
            <limit effort="${max_effort}" lower="${-175 * PI / 180}" upper="${175 * PI / 180}"
                velocity="${max_velocity}" />
            <safety_controller
                soft_lower_limit="${-173 * PI / 180}"
                soft_upper_limit="${173 * PI / 180}"
                k_position="${safety_controller_k_pos}"
                k_velocity="${safety_controller_k_vel}"
            />
            <dynamics damping="${joint_damping}" friction="${joint_friction}" />
        </joint>

        <link name="${robot_name}_link_7">
            <inertial>
                <origin rpy="0 0 0" xyz="3.0000e-06 -2.0000e-06 1.3782e-02" />
                <mass value="0.280474" />
                <inertia ixx="0.000185" ixy="0.0" ixz="0.0" iyy="0.000185" iyz="0.0" izz="0.000323" />
            </inertial>
            <visual>
                <origin rpy="0 0 0" xyz="0.0 0.0 -1.2705" />
                <geometry>
                    <mesh filename="package://lbr_description/meshes/med14/visual/link_7.dae" />
                </geometry>
            </visual>
            <collision>
                <origin rpy="0 0 0" xyz="0.0 0.0 -1.2705" />
                <geometry>
                    <mesh filename="package://lbr_description/meshes/med14/collision/link_7.stl" />
                </geometry>
            </collision>
        </link>

        <joint name="${robot_name}_joint_ee" type="fixed">
            <parent link="${robot_name}_link_7" />
            <child link="${robot_name}_link_ee" />
            <origin xyz="0 0 0.035" rpy="0 0 0" />
        </joint>

        <link name="${robot_name}_link_ee">
        </link>

        <!-- extensions -->
        <xacro:med_gazebo robot_name="${robot_name}" />
        <xacro:lbr_transmission hardware_interface="${hardware_interface}"
            robot_name="${robot_name}" />
    </xacro:macro>

</robot>