<?xml version="1.0"?>

<robot xmlns:xacro="http://www.ros.org/wiki/xacro">

    <!-- include gazebo specifications -->
    <xacro:include filename="$(find lbr_description)/urdf/med.gazebo.xacro"/>

    <!-- include transmission for ros_control -->
    <xacro:include filename="$(find lbr_description)/urdf/lbr.transmission.xacro"/>

    <!-- include materials -->
    <xacro:include filename="$(find lbr_description)/urdf/lbr.materials.xacro"/>

    <!-- some constants -->
    <xacro:property name="PI" value="3.1415926535897931"/>
    <xacro:property name="safety_controller_k_pos" value="100"/>
    <xacro:property name="safety_controller_k_vel" value="2"/> 
    <xacro:property name="joint_damping" value="10.0"/>
    <xacro:property name="joint_friction" value="0.1"/>
    <xacro:property name="max_effort" value="300"/>
    <xacro:property name="max_velocity" value="10"/>

    <!-- robot as extracted via https://github.com/syuntoku14/fusion2urdf -->
    <xacro:macro name="med7" params="hardware_interface *origin parent robot_name">

        <!--joint between {parent} and link_0-->
        <joint name="${parent}_${robot_name}_joint" type="fixed">
            <xacro:insert_block name="origin"/>
            <parent link="${parent}"/>
            <child link="${robot_name}_link_0"/>=
        </joint>

        <link name="${robot_name}_link_0">
            <inertial>
            <origin rpy="0 0 0" xyz="-0.0018958727522859222 -8.736009549202623e-09 0.07626305487275586"/>
            <mass value="46.20540698229506"/>
            <inertia ixx="0.250291" ixy="-0.0" ixz="-0.004435" iyy="0.255257" iyz="-0.0" izz="0.351803"/>
            </inertial>
            <visual>
            <origin rpy="0 0 0" xyz="0 0 0"/>
            <geometry>
                <mesh filename="package://lbr_description/meshes/med7/visual/link_0.stl"/>
            </geometry>
            <material name="white"/>
            </visual>
            <collision>
            <origin rpy="0 0 0" xyz="0 0 0"/>
            <geometry>
                <mesh filename="package://lbr_description/meshes/med7/collision/link_0.stl"/>
            </geometry>
            </collision>
        </link>

        <joint name="${robot_name}_joint_1" type="revolute">
            <origin rpy="0 0 0" xyz="0.0 0.0 0.1475"/>
            <parent link="${robot_name}_link_0"/>
            <child link="${robot_name}_link_1"/>
            <axis xyz="0.0 0.0 0.01"/>
            <limit effort="${max_effort}" lower="${-170 * PI / 180}" upper="${170 * PI / 180}" velocity="${max_velocity}"/>
            <safety_controller 
                soft_lower_limit="${-168 * PI / 180}"
                soft_upper_limit="${168 * PI / 180}"
                k_position="${safety_controller_k_pos}"
                k_velocity="${safety_controller_k_vel}"
            /> 
            <dynamics damping="${joint_damping}" friction="${joint_friction}"/>
        </joint>

        <link name="${robot_name}_link_1">
            <inertial>
            <origin rpy="0 0 0" xyz="5.010328793588479e-08 -0.03481903813472808 0.12329857163085542"/>
            <mass value="21.161828997118327"/>
            <inertia ixx="0.133324" ixy="-0.0" ixz="0.0" iyy="0.127214" iyz="0.023673" izz="0.047155"/>
            </inertial>
            <visual>
            <origin rpy="0 0 0" xyz="-0.0 0.0 -0.1475"/>
            <geometry>
                <mesh filename="package://lbr_description/meshes/med7/visual/link_1.stl"/>
            </geometry>
            <material name="white"/>
            </visual>
            <collision>
            <origin rpy="0 0 0" xyz="-0.0 0.0 -0.1475"/>
            <geometry>
                <mesh filename="package://lbr_description/meshes/med7/collision/link_1.stl"/>
            </geometry>
            </collision>
        </link>

        <joint name="${robot_name}_joint_2" type="revolute">
            <origin rpy="0 0 0" xyz="-0.0 -0.0105 0.1925"/>
            <parent link="${robot_name}_link_1"/>
            <child link="${robot_name}_link_2"/>
            <axis xyz="0.0 0.01 0.0"/>
            <limit effort="${max_effort}" lower="${-120 * PI / 180}" upper="${120 * PI / 180}" velocity="${max_velocity}"/>
            <safety_controller 
                soft_lower_limit="${-118 * PI / 180}"
                soft_upper_limit="${118 * PI / 180}"
                k_position="${safety_controller_k_pos}"
                k_velocity="${safety_controller_k_vel}"
            /> 
            <dynamics damping="${joint_damping}" friction="${joint_friction}"/>
        </joint>

        <link name="${robot_name}_link_2">
            <inertial>
            <origin rpy="0 0 0" xyz="2.958275959973659e-08 0.03979295468456965 0.08694361150855662"/>
            <mass value="25.13966081800886"/>
            <inertia ixx="0.19763" ixy="-0.0" ixz="0.0" iyy="0.187553" iyz="0.036718" izz="0.060269"/>
            </inertial>
            <visual>
            <origin rpy="0 0 0" xyz="0.0 0.0105 -0.34"/>
            <geometry>
                <mesh filename="package://lbr_description/meshes/med7/visual/link_2.stl"/>
            </geometry>
            <material name="white"/>
            </visual>
            <collision>
            <origin rpy="0 0 0" xyz="0.0 0.0105 -0.34"/>
            <geometry>
                <mesh filename="package://lbr_description/meshes/med7/collision/link_2.stl"/>
            </geometry>
            </collision>
        </link>

        <joint name="${robot_name}_joint_3" type="revolute">
            <origin rpy="0 0 0" xyz="0.0 0.0105 0.2075"/>
            <parent link="${robot_name}_link_2"/>
            <child link="${robot_name}_link_3"/>
            <axis xyz="0.0 0.0 0.01"/>
            <limit effort="${max_effort}" lower="${-170 * PI / 180}" upper="${170 * PI / 180}" velocity="${max_velocity}"/>
            <safety_controller 
                soft_lower_limit="${-168 * PI / 180}"
                soft_upper_limit="${168 * PI / 180}"
                k_position="${safety_controller_k_pos}"
                k_velocity="${safety_controller_k_vel}"
            /> 
            <dynamics damping="${joint_damping}" friction="${joint_friction}"/>
        </joint>

        <link name="${robot_name}_link_3">
            <inertial>
            <origin rpy="0 0 0" xyz="-5.010330962930412e-08 0.03481903813473644 0.1232985716309013"/>
            <mass value="21.1618289971097"/>
            <inertia ixx="0.133324" ixy="-0.0" ixz="-0.0" iyy="0.127214" iyz="-0.023673" izz="0.047155"/>
            </inertial>
            <visual>
            <origin rpy="0 0 0" xyz="0.0 -0.0 -0.5475"/>
            <geometry>
                <mesh filename="package://lbr_description/meshes/med7/visual/link_3.stl"/>
            </geometry>
            <material name="white"/>
            </visual>
            <collision>
            <origin rpy="0 0 0" xyz="0.0 -0.0 -0.5475"/>
            <geometry>
                <mesh filename="package://lbr_description/meshes/med7/collision/link_3.stl"/>
            </geometry>
            </collision>
        </link>

        <joint name="${robot_name}_joint_4" type="revolute">
            <origin rpy="0 0 0" xyz="0.0 0.0105 0.1925"/>
            <parent link="${robot_name}_link_3"/>
            <child link="${robot_name}_link_4"/>
            <axis xyz="0.0 -0.01 0.0"/>
            <limit effort="${max_effort}" lower="${-120 * PI / 180}" upper="${120 * PI / 180}" velocity="${max_velocity}"/>
            <safety_controller 
                soft_lower_limit="${-118 * PI / 180}"
                soft_upper_limit="${118 * PI / 180}"
                k_position="${safety_controller_k_pos}"
                k_velocity="${safety_controller_k_vel}"
            /> 
            <dynamics damping="${joint_damping}" friction="${joint_friction}"/>
        </joint>

        <link name="${robot_name}_link_4">
            <inertial>
            <origin rpy="0 0 0" xyz="-3.025230048709993e-08 -0.03979329512443697 0.08694363375610437"/>
            <mass value="25.139648831600116"/>
            <inertia ixx="0.197618" ixy="-0.0" ixz="-0.0" iyy="0.187546" iyz="-0.036716" izz="0.060263"/>
            </inertial>
            <visual>
            <origin rpy="0 0 0" xyz="-0.0 -0.0105 -0.74"/>
            <geometry>
                <mesh filename="package://lbr_description/meshes/med7/visual/link_4.stl"/>
            </geometry>
            <material name="white"/>
            </visual>
            <collision>
            <origin rpy="0 0 0" xyz="-0.0 -0.0105 -0.74"/>
            <geometry>
                <mesh filename="package://lbr_description/meshes/med7/collision/link_4.stl"/>
            </geometry>
            </collision>
        </link>

        <joint name="${robot_name}_joint_5" type="revolute">
            <origin rpy="0 0 0" xyz="-0.0 -0.0105 0.2075"/>
            <parent link="${robot_name}_link_4"/>
            <child link="${robot_name}_link_5"/>
            <axis xyz="0.0 0.0 0.01"/>
            <limit effort="${max_effort}" lower="${-170 * PI / 180}" upper="${170 * PI / 180}" velocity="${max_velocity}"/>
            <safety_controller 
                soft_lower_limit="${-168 * PI / 180}"
                soft_upper_limit="${168 * PI / 180}"
                k_position="${safety_controller_k_pos}"
                k_velocity="${safety_controller_k_vel}"
            /> 
            <dynamics damping="${joint_damping}" friction="${joint_friction}"/>
        </joint>

        <link name="${robot_name}_link_5">
            <inertial>
            <origin rpy="0 0 0" xyz="3.887174133882675e-08 -0.02982428408876193 0.07626701716135398"/>
            <mass value="9.534880920206515"/>
            <inertia ixx="0.052905" ixy="0.0" ixz="-0.0" iyy="0.044495" iyz="0.017493" izz="0.023991"/>
            </inertial>
            <visual>
            <origin rpy="0 0 0" xyz="0.0 0.0 -0.9475"/>
            <geometry>
                <mesh filename="package://lbr_description/meshes/med7/visual/link_5.stl"/>
            </geometry>
            <material name="white"/>
            </visual>
            <collision>
            <origin rpy="0 0 0" xyz="0.0 0.0 -0.9475"/>
            <geometry>
                <mesh filename="package://lbr_description/meshes/med7/collision/link_5.stl"/>
            </geometry>
            </collision>
        </link>

        <joint name="${robot_name}_joint_6" type="revolute">
            <origin rpy="0 0 0" xyz="0.0 -0.0707 0.1925"/>
            <parent link="${robot_name}_link_5"/>
            <child link="${robot_name}_link_6"/>
            <axis xyz="0.0 0.01 0.0"/>
            <limit effort="${max_effort}" lower="${-120 * PI / 180}" upper="${120 * PI / 180}" velocity="${max_velocity}"/>
            <safety_controller 
                soft_lower_limit="${-118 * PI / 180}"
                soft_upper_limit="${118 * PI / 180}"
                k_position="${safety_controller_k_pos}"
                k_velocity="${safety_controller_k_vel}"
            /> 
            <dynamics damping="${joint_damping}" friction="${joint_friction}"/>
        </joint>

        <link name="${robot_name}_link_6">
            <inertial>
            <origin rpy="0 0 0" xyz="-7.073221144775636e-07 0.07101990943401648 0.004952526180360017"/>
            <mass value="14.987109331100873"/>
            <inertia ixx="0.044068" ixy="-0.0" ixz="1e-06" iyy="0.042427" iyz="0.001941" izz="0.028865"/>
            </inertial>
            <visual>
            <origin rpy="0 0 0" xyz="0.0 0.0707 -1.14"/>
            <geometry>
                <mesh filename="package://lbr_description/meshes/med7/visual/link_6.stl"/>
            </geometry>
            <material name="white"/>
            </visual>
            <collision>
            <origin rpy="0 0 0" xyz="0.0 0.0707 -1.14"/>
            <geometry>
                <mesh filename="package://lbr_description/meshes/med7/collision/link_6.stl"/>
            </geometry>
            </collision>
        </link>

        <joint name="${robot_name}_joint_7" type="revolute">
            <origin rpy="0 0 0" xyz="0.0 0.0707 0.091"/>
            <parent link="${robot_name}_link_6"/>
            <child link="${robot_name}_link_7"/>
            <axis xyz="0.0 0.0 0.01"/>
            <limit effort="${max_effort}" lower="${-175 * PI / 180}" upper="${175 * PI / 180}" velocity="${max_velocity}"/>
            <safety_controller 
                soft_lower_limit="${-173 * PI / 180}"
                soft_upper_limit="${173 * PI / 180}"
                k_position="${safety_controller_k_pos}"
                k_velocity="${safety_controller_k_vel}"
            /> 
            <dynamics damping="${joint_damping}" friction="${joint_friction}"/>
        </joint>

        <link name="${robot_name}_link_7">
            <inertial>
            <origin rpy="0 0 0" xyz="3.1218274599808524e-06 -1.6358155634513969e-06 0.013782295521067356"/>
            <mass value="1.6178339975962697"/>
            <inertia ixx="0.001066" ixy="0.0" ixz="-0.0" iyy="0.001066" iyz="0.0" izz="0.001864"/>
            </inertial>
            <visual>
            <origin rpy="0 0 0" xyz="-0.0 -0.0 -1.231"/>
            <geometry>
                <mesh filename="package://lbr_description/meshes/med7/visual/link_7.stl"/>
            </geometry>
            <material name="silver"/>
            </visual>
            <collision>
            <origin rpy="0 0 0" xyz="-0.0 -0.0 -1.231"/>
            <geometry>
                <mesh filename="package://lbr_description/meshes/med7/collision/link_7.stl"/>
            </geometry>
            </collision>
        </link>

        <joint name="${robot_name}_joint_ee" type="fixed">
            <parent link="${robot_name}_link_7"/>
            <child link="${robot_name}_link_ee"/>
            <origin xyz="0 0 0.035" rpy="0 0 0"/>
        </joint>
        
        <link name="${robot_name}_link_ee">
        </link>

        <!-- extensions -->
        <xacro:med_gazebo robot_name="${robot_name}"/>
        <xacro:lbr_transmission hardware_interface="${hardware_interface}" robot_name="${robot_name}"/>
    </xacro:macro>

</robot>
