<?xml version="1.0"?>

<robot xmlns:xacro="http://www.ros.org/wiki/xacro">

    <!-- some constants -->
    <xacro:property name="PI" value="3.1415926535897931" />
    <xacro:property name="joint_damping" value="10.0" />
    <xacro:property name="joint_friction" value="0.1" />
    <xacro:property name="A1_position_limit" value="170" />
    <xacro:property name="A2_position_limit" value="120" />
    <xacro:property name="A3_position_limit" value="170" />
    <xacro:property name="A4_position_limit" value="120" />
    <xacro:property name="A5_position_limit" value="170" />
    <xacro:property name="A6_position_limit" value="120" />
    <xacro:property name="A7_position_limit" value="175" />
    <xacro:property name="A1_velocity_limit" value="85" />
    <xacro:property name="A2_velocity_limit" value="85" />
    <xacro:property name="A3_velocity_limit" value="100" />
    <xacro:property name="A4_velocity_limit" value="75" />
    <xacro:property name="A5_velocity_limit" value="130" />
    <xacro:property name="A6_velocity_limit" value="135" />
    <xacro:property name="A7_velocity_limit" value="135" />
    <xacro:property name="effort_limit" value="200" />

    <!-- includes -->
    <xacro:include filename="$(find lbr_description)/gazebo/lbr.gazebo.xacro" />
    <xacro:include filename="$(find lbr_ros2_control)/config/lbr_system_interface.xacro" />

    <!-- robot as extracted via https://github.com/syuntoku14/fusion2urdf -->
    <xacro:macro name="iiwa14"
        params="robot_name:=^|lbr port_id:=^|30200 sim:=^|true">

        <link name="link_0">
            <inertial>
                <origin rpy="0 0 0" xyz="-0.012822 0.0 0.071507" />
                <mass value="7.050378" />
                <inertia ixx="0.031226" ixy="0.0" ixz="0.000871" iyy="0.039697" iyz="0.0"
                    izz="0.043102" />
            </inertial>
            <visual>
                <origin rpy="0 0 0" xyz="0 0 0" />
                <geometry>
                    <mesh filename="package://lbr_description/meshes/iiwa14/visual/link_0.dae" />
                </geometry>
            </visual>
            <collision>
                <origin rpy="0 0 0" xyz="0 0 0" />
                <geometry>
                    <mesh filename="package://lbr_description/meshes/iiwa14/collision/link_0.stl" />
                </geometry>
            </collision>
        </link>

        <joint name="A1" type="revolute">
            <origin rpy="0 0 0" xyz="0.0 0.0 0.1475" />
            <parent link="link_0" />
            <child link="link_1" />
            <axis xyz="0.0 0.0 1.0" />
            <limit effort="${effort_limit}" lower="${-A1_position_limit * PI / 180}"
                upper="${A1_position_limit * PI / 180}"
                velocity="${A1_velocity_limit * PI / 180}" />
            <dynamics damping="${joint_damping}" friction="${joint_friction}" />
        </joint>

        <link name="link_1">
            <inertial>
                <origin rpy="0 0 0" xyz="0.0 -0.033795 0.132404" />
                <mass value="5.289529" />
                <inertia ixx="0.042462" ixy="0.0" ixz="0.0" iyy="0.042838" iyz="0.006341"
                    izz="0.01587" />
            </inertial>
            <visual>
                <origin rpy="0 0 0" xyz="0.0 0.0 -0.1475" />
                <geometry>
                    <mesh filename="package://lbr_description/meshes/iiwa14/visual/link_1.dae" />
                </geometry>
            </visual>
            <collision>
                <origin rpy="0 0 0" xyz="0.0 0.0 -0.1475" />
                <geometry>
                    <mesh filename="package://lbr_description/meshes/iiwa14/collision/link_1.stl" />
                </geometry>
            </collision>
        </link>

        <joint name="A2" type="revolute">
            <origin rpy="0 0 0" xyz="0.0 -0.01 0.2125" />
            <parent link="link_1" />
            <child link="link_2" />
            <axis xyz="0.0 1.0 0.0" />
            <limit effort="${effort_limit}" lower="${-A2_position_limit * PI / 180}"
                upper="${A2_position_limit * PI / 180}"
                velocity="${A2_velocity_limit * PI / 180}" />
            <dynamics damping="${joint_damping}" friction="${joint_friction}" />
        </joint>

        <link name="link_2">
            <inertial>
                <origin rpy="0 0 0" xyz="0.000136 0.047548 0.076322" />
                <mass value="5.688888" />
                <inertia ixx="0.055182" ixy="-3.3e-05" ixz="5.6e-05" iyy="0.053983" iyz="0.010034"
                    izz="0.016523" />
            </inertial>
            <visual>
                <origin rpy="0 0 0" xyz="0.0 0.01 -0.36" />
                <geometry>
                    <mesh filename="package://lbr_description/meshes/iiwa14/visual/link_2.dae" />
                </geometry>
            </visual>
            <collision>
                <origin rpy="0 0 0" xyz="0.0 0.01 -0.36" />
                <geometry>
                    <mesh filename="package://lbr_description/meshes/iiwa14/collision/link_2.stl" />
                </geometry>
            </collision>
        </link>

        <joint name="A3" type="revolute">
            <origin rpy="0 0 0" xyz="0.0 0.01 0.228" />
            <parent link="link_2" />
            <child link="link_3" />
            <axis xyz="0.0 0.0 1.0" />
            <limit effort="${effort_limit}" lower="${-A3_position_limit * PI / 180}"
                upper="${A3_position_limit * PI / 180}"
                velocity="${A3_velocity_limit * PI / 180}" />
            <dynamics damping="${joint_damping}" friction="${joint_friction}" />
        </joint>

        <link name="link_3">
            <inertial>
                <origin rpy="0 0 0" xyz="0.0 0.034913 0.123108" />
                <mass value="3.461245" />
                <inertia ixx="0.02172" ixy="0.0" ixz="0.0" iyy="0.02073" iyz="-0.003845"
                    izz="0.007701" />
            </inertial>
            <visual>
                <origin rpy="0 0 0" xyz="0.0 0.0 -0.588" />
                <geometry>
                    <mesh filename="package://lbr_description/meshes/iiwa14/visual/link_3.dae" />
                </geometry>
            </visual>
            <collision>
                <origin rpy="0 0 0" xyz="0.0 0.0 -0.588" />
                <geometry>
                    <mesh filename="package://lbr_description/meshes/iiwa14/collision/link_3.stl" />
                </geometry>
            </collision>
        </link>

        <joint name="A4" type="revolute">
            <origin rpy="0 0 0" xyz="0.0 0.0105 0.192" />
            <parent link="link_3" />
            <child link="link_4" />
            <axis xyz="0.0 -1.0 0.0" />
            <limit effort="${effort_limit}" lower="${-A4_position_limit * PI / 180}"
                upper="${A4_position_limit * PI / 180}"
                velocity="${A4_velocity_limit * PI / 180}" />
            <dynamics damping="${joint_damping}" friction="${joint_friction}" />
        </joint>

        <link name="link_4">
            <inertial>
                <origin rpy="0 0 0" xyz="0.0 -0.039793 0.086944" />
                <mass value="4.122995" />
                <inertia ixx="0.03241" ixy="0.0" ixz="0.0" iyy="0.030758" iyz="-0.006022"
                    izz="0.009883" />
            </inertial>
            <visual>
                <origin rpy="0 0 0" xyz="0.0 -0.0105 -0.78" />
                <geometry>
                    <mesh filename="package://lbr_description/meshes/iiwa14/visual/link_4.dae" />
                </geometry>
            </visual>
            <collision>
                <origin rpy="0 0 0" xyz="0.0 -0.0105 -0.78" />
                <geometry>
                    <mesh filename="package://lbr_description/meshes/iiwa14/collision/link_4.stl" />
                </geometry>
            </collision>
        </link>

        <joint name="A5" type="revolute">
            <origin rpy="0 0 0" xyz="0.0 -0.0105 0.2075" />
            <parent link="link_4" />
            <child link="link_5" />
            <axis xyz="0.0 0.0 1.0" />
            <limit effort="${effort_limit}" lower="${-A5_position_limit * PI / 180}"
                upper="${A5_position_limit * PI / 180}"
                velocity="${A5_velocity_limit * PI / 180}" />
            <dynamics damping="${joint_damping}" friction="${joint_friction}" />
        </joint>

        <link name="link_5">
            <inertial>
                <origin rpy="0 0 0" xyz="0.0 -0.029824 0.076267" />
                <mass value="1.563756" />
                <inertia ixx="0.008677" ixy="0.0" ixz="0.0" iyy="0.007297" iyz="0.002869"
                    izz="0.003935" />
            </inertial>
            <visual>
                <origin rpy="0 0 0" xyz="0.0 0.0 -0.9875" />
                <geometry>
                    <mesh filename="package://lbr_description/meshes/iiwa14/visual/link_5.dae" />
                </geometry>
            </visual>
            <collision>
                <origin rpy="0 0 0" xyz="0.0 0.0 -0.9875" />
                <geometry>
                    <mesh filename="package://lbr_description/meshes/iiwa14/collision/link_5.stl" />
                </geometry>
            </collision>
        </link>

        <joint name="A6" type="revolute">
            <origin rpy="0 0 0" xyz="0.0 -0.0707 0.1925" />
            <parent link="link_5" />
            <child link="link_6" />
            <axis xyz="0.0 1.0 0.0" />
            <limit effort="${effort_limit}" lower="${-A6_position_limit * PI / 180}"
                upper="${A6_position_limit * PI / 180}"
                velocity="${A6_velocity_limit * PI / 180}" />
            <dynamics damping="${joint_damping}" friction="${joint_friction}" />
        </joint>

        <link name="link_6">
            <inertial>
                <origin rpy="0 0 0" xyz="0.0 0.07102 0.00495" />
                <mass value="2.457878" />
                <inertia ixx="0.007227" ixy="0.0" ixz="0.0" iyy="0.006958" iyz="0.000318"
                    izz="0.004734" />
            </inertial>
            <visual>
                <origin rpy="0 0 0" xyz="0.0 0.0707 -1.18" />
                <geometry>
                    <mesh filename="package://lbr_description/meshes/iiwa14/visual/link_6.dae" />
                </geometry>
            </visual>
            <collision>
                <origin rpy="0 0 0" xyz="0.0 0.0707 -1.18" />
                <geometry>
                    <mesh filename="package://lbr_description/meshes/iiwa14/collision/link_6.stl" />
                </geometry>
            </collision>
        </link>

        <joint name="A7" type="revolute">
            <origin rpy="0 0 0" xyz="0.0 0.0707 0.091" />
            <parent link="link_6" />
            <child link="link_7" />
            <axis xyz="0.0 0.0 1.0" />
            <limit effort="${effort_limit}" lower="${-A7_position_limit * PI / 180}"
                upper="${A7_position_limit * PI / 180}"
                velocity="${A7_velocity_limit * PI / 180}" />
            <dynamics damping="${joint_damping}" friction="${joint_friction}" />
        </joint>

        <link name="link_7">
            <inertial>
                <origin rpy="0 0 0" xyz="3.0000e-06 -2.0000e-06 1.3782e-02" />
                <mass value="0.265331" />
                <inertia ixx="0.000175" ixy="0.0" ixz="0.0" iyy="0.000175" iyz="0.0" izz="0.000306" />
            </inertial>
            <visual>
                <origin rpy="0 0 0" xyz="0.0 0.0 -1.271" />
                <geometry>
                    <mesh filename="package://lbr_description/meshes/iiwa14/visual/link_7.dae" />
                </geometry>
            </visual>
            <collision>
                <origin rpy="0 0 0" xyz="0.0 0.0 -1.271" />
                <geometry>
                    <mesh filename="package://lbr_description/meshes/iiwa14/collision/link_7.stl" />
                </geometry>
            </collision>
        </link>

        <joint name="joint_ee" type="fixed">
            <parent link="link_7" />
            <child link="link_ee" />
            <origin xyz="0 0 0.035" rpy="0 0 0" />
        </joint>

        <link name="link_ee">
        </link>

        <xacro:lbr_gazebo robot_name="${robot_name}" />
        <!-- TODO: move modes to args, decouple urdf/gazebo/controls -->
        <xacro:lbr_system_interface
            A1_position_limit="${A1_position_limit * PI / 180}"
            A2_position_limit="${A2_position_limit * PI / 180}"
            A3_position_limit="${A3_position_limit * PI / 180}"
            A4_position_limit="${A4_position_limit * PI / 180}"
            A5_position_limit="${A5_position_limit * PI / 180}"
            A6_position_limit="${A6_position_limit * PI / 180}"
            A7_position_limit="${A7_position_limit * PI / 180}"
            A1_velocity_limit="${A1_velocity_limit * PI / 180}"
            A2_velocity_limit="${A2_velocity_limit * PI / 180}"
            A3_velocity_limit="${A3_velocity_limit * PI / 180}"
            A4_velocity_limit="${A4_velocity_limit * PI / 180}"
            A5_velocity_limit="${A5_velocity_limit * PI / 180}"
            A6_velocity_limit="${A6_velocity_limit * PI / 180}"
            A7_velocity_limit="${A7_velocity_limit * PI / 180}"
            max_torque="${effort_limit}"
            sim="${sim}" remote_host="INADDR_ANY" port_id="${port_id}" />

    </xacro:macro>
</robot>