<sdf version='1.6'>
  <model name='iiwa'>
    <link name='base_link'>
      <pose frame=''>0 0 0 0 -0 0</pose>
      <inertial>
        <pose frame=''>-0.012822 -0 0.071507 0 -0 0</pose>
        <mass>42.9891</mass>
        <inertia>
          <ixx>0.190401</ixx>
          <ixy>0</ixy>
          <ixz>0.005312</ixz>
          <iyy>0.242047</iyy>
          <iyz>0</iyz>
          <izz>0.262814</izz>
        </inertia>
      </inertial>
      <collision name='base_link_collision'>
        <pose frame=''>0 0 0 0 -0 0</pose>
        <geometry>
          <mesh>
            <scale>1 1 1</scale>
            <uri>model://iiwa14/meshes/base_link.stl</uri>
          </mesh>
        </geometry>
      </collision>
      <visual name='base_link_visual'>
        <pose frame=''>0 0 0 0 -0 0</pose>
        <geometry>
          <mesh>
            <scale>1 1 1</scale>
            <uri>model://iiwa14/meshes/base_link.stl</uri>
          </mesh>
        </geometry>
      </visual>
    </link>
    <link name='link_1'>
      <pose frame=''>0 0 0.1475 0 -0 0</pose>
      <inertial>
        <pose frame=''>0 -0.033795 0.132404 0 -0 0</pose>
        <mass>32.2525</mass>
        <inertia>
          <ixx>0.258906</ixx>
          <ixy>-0</ixy>
          <ixz>-0</ixz>
          <iyy>0.261201</iyy>
          <iyz>0.038666</iyz>
          <izz>0.096765</izz>
        </inertia>
      </inertial>
      <collision name='link_1_collision'>
        <pose frame=''>-0 0 -0.1475 0 -0 0</pose>
        <geometry>
          <mesh>
            <scale>1 1 1</scale>
            <uri>model://iiwa14/meshes/link_1.stl</uri>
          </mesh>
        </geometry>
      </collision>
      <visual name='link_1_visual'>
        <pose frame=''>-0 0 -0.1475 0 -0 0</pose>
        <geometry>
          <mesh>
            <scale>1 1 1</scale>
            <uri>model://iiwa14/meshes/link_1.stl</uri>
          </mesh>
        </geometry>
      </visual>
    </link>
    <joint name='A1' type='revolute'>
      <child>link_1</child>
      <parent>base_link</parent>
      <axis>
        <xyz>0 0 0.01</xyz>
        <limit>
          <lower>-2.96706</lower>
          <upper>2.96706</upper>
          <effort>100</effort>
          <velocity>1.48353</velocity>
        </limit>
        <dynamics>
          <spring_reference>0</spring_reference>
          <spring_stiffness>0</spring_stiffness>
        </dynamics>
        <use_parent_model_frame>1</use_parent_model_frame>
      </axis>
    </joint>
    <link name='link_2'>
      <pose frame=''>0 -0.01 0.36 0 -0 0</pose>
      <inertial>
        <pose frame=''>0.000152 0.051987 0.058801 0 -0 0</pose>
        <mass>31.0204</mass>
        <inertia>
          <ixx>0.240168</ixx>
          <ixy>-0.000179</ixy>
          <ixz>0.000259</ixz>
          <iyy>0.238795</iyy>
          <iyz>0.038362</iyz>
          <izz>0.086485</izz>
        </inertia>
      </inertial>
      <collision name='link_2_collision'>
        <pose frame=''>-0 0.01 -0.36 0 -0 0</pose>
        <geometry>
          <mesh>
            <scale>1 1 1</scale>
            <uri>model://iiwa14/meshes/link_2.stl</uri>
          </mesh>
        </geometry>
      </collision>
      <visual name='link_2_visual'>
        <pose frame=''>-0 0.01 -0.36 0 -0 0</pose>
        <geometry>
          <mesh>
            <scale>1 1 1</scale>
            <uri>model://iiwa14/meshes/link_2.stl</uri>
          </mesh>
        </geometry>
      </visual>
    </link>
    <joint name='A2' type='revolute'>
      <child>link_2</child>
      <parent>link_1</parent>
      <axis>
        <xyz>0 0.01 0</xyz>
        <limit>
          <lower>-2.0944</lower>
          <upper>2.0944</upper>
          <effort>100</effort>
          <velocity>1.48353</velocity>
        </limit>
        <dynamics>
          <spring_reference>0</spring_reference>
          <spring_stiffness>0</spring_stiffness>
        </dynamics>
        <use_parent_model_frame>1</use_parent_model_frame>
      </axis>
    </joint>
    <static>0</static>
    <plugin name='control' filename='libgazebo_ros_control.so'/>
  </model>
</sdf>
