<sdf version='1.6'>
  <model name='iiwa7'>
    <link name='base_link'>
      <pose frame=''>0 0 0 0 -0 0</pose>
      <inertial>
        <pose frame=''>-0.012836 0 0.070107 0 -0 0</pose>
        <mass>30.3248</mass>
        <inertia>
          <ixx>0.111667</ixx>
          <ixy>0</ixy>
          <ixz>0.004812</ixz>
          <iyy>0.139457</iyy>
          <iyz>-0</iyz>
          <izz>0.133156</izz>
        </inertia>
      </inertial>
      <collision name='base_link_collision'>
        <pose frame=''>0 0 0 0 -0 0</pose>
        <geometry>
          <mesh>
            <scale>1 1 1</scale>
            <uri>model://iiwa7/meshes/base_link.stl</uri>
          </mesh>
        </geometry>
      </collision>
      <visual name='base_link_visual'>
        <pose frame=''>0 0 0 0 -0 0</pose>
        <geometry>
          <mesh>
            <scale>1 1 1</scale>
            <uri>model://iiwa7/meshes/base_link.stl</uri>
          </mesh>
        </geometry>
      </visual>
    </link>
    <link name='link_1'>
      <pose frame=''>0 0 0.1475 0 -0 0</pose>
      <inertial>
        <pose frame=''>0 -0.034734 0.123516 0 -0 0</pose>
        <mass>21.2139</mass>
        <inertia>
          <ixx>0.134131</ixx>
          <ixy>-0</ixy>
          <ixz>0</ixz>
          <iyy>0.127957</iyy>
          <iyz>0.023881</iyz>
          <izz>0.047328</izz>
        </inertia>
      </inertial>
      <collision name='link_1_collision'>
        <pose frame=''>-0 0 -0.1475 0 -0 0</pose>
        <geometry>
          <mesh>
            <scale>1 1 1</scale>
            <uri>model://iiwa7/meshes/link_1.stl</uri>
          </mesh>
        </geometry>
      </collision>
      <visual name='link_1_visual'>
        <pose frame=''>-0 0 -0.1475 0 -0 0</pose>
        <geometry>
          <mesh>
            <scale>1 1 1</scale>
            <uri>model://iiwa7/meshes/link_1.stl</uri>
          </mesh>
        </geometry>
      </visual>
    </link>
    <joint name='A1' type='revolute'>
      <child>link_1</child>
      <parent>base_link</parent>
      <axis>
        <xyz>0 0 0.01</xyz>
        <limit>
          <lower>-2.96706</lower>
          <upper>2.96706</upper>
          <effort>100</effort>
          <velocity>1.71042</velocity>
        </limit>
        <dynamics>
          <spring_reference>0</spring_reference>
          <spring_stiffness>0</spring_stiffness>
        </dynamics>
        <use_parent_model_frame>1</use_parent_model_frame>
      </axis>
    </joint>
    <link name='link_2'>
      <pose frame=''>0 -0.0105 0.3405 0 -0 0</pose>
      <inertial>
        <pose frame=''>0 0.044916 0.067325 0 -0 0</pose>
        <mass>21.3976</mass>
        <inertia>
          <ixx>0.133839</ixx>
          <ixy>-0</ixy>
          <ixz>0</ixz>
          <iyy>0.12753</iyy>
          <iyz>0.022271</iyz>
          <izz>0.047853</izz>
        </inertia>
      </inertial>
      <collision name='link_2_collision'>
        <pose frame=''>0 0.0105 -0.3405 0 -0 0</pose>
        <geometry>
          <mesh>
            <scale>1 1 1</scale>
            <uri>model://iiwa7/meshes/link_2.stl</uri>
          </mesh>
        </geometry>
      </collision>
      <visual name='link_2_visual'>
        <pose frame=''>0 0.0105 -0.3405 0 -0 0</pose>
        <geometry>
          <mesh>
            <scale>1 1 1</scale>
            <uri>model://iiwa7/meshes/link_2.stl</uri>
          </mesh>
        </geometry>
      </visual>
    </link>
    <joint name='A2' type='revolute'>
      <child>link_2</child>
      <parent>link_1</parent>
      <axis>
        <xyz>0 0.01 0</xyz>
        <limit>
          <lower>-2.0944</lower>
          <upper>2.0944</upper>
          <effort>100</effort>
          <velocity>1.71042</velocity>
        </limit>
        <dynamics>
          <spring_reference>0</spring_reference>
          <spring_stiffness>0</spring_stiffness>
        </dynamics>
        <use_parent_model_frame>1</use_parent_model_frame>
      </axis>
    </joint>
    <link name='link_3'>
      <pose frame=''>0 0 0.515 0 -0 0</pose>
      <inertial>
        <pose frame=''>-0 0.029564 0.136503 0 -0 0</pose>
        <mass>24.9237</mass>
        <inertia>
          <ixx>0.196866</ixx>
          <ixy>-0</ixy>
          <ixz>0</ixz>
          <iyy>0.186889</iyy>
          <iyz>-0.038259</iyz>
          <izz>0.059722</izz>
        </inertia>
      </inertial>
      <collision name='link_3_collision'>
        <pose frame=''>0 0 -0.515 0 -0 0</pose>
        <geometry>
          <mesh>
            <scale>1 1 1</scale>
            <uri>model://iiwa7/meshes/link_3.stl</uri>
          </mesh>
        </geometry>
      </collision>
      <visual name='link_3_visual'>
        <pose frame=''>0 0 -0.515 0 -0 0</pose>
        <geometry>
          <mesh>
            <scale>1 1 1</scale>
            <uri>model://iiwa7/meshes/link_3.stl</uri>
          </mesh>
        </geometry>
      </visual>
    </link>
    <joint name='A3' type='revolute'>
      <child>link_3</child>
      <parent>link_2</parent>
      <axis>
        <xyz>0 0 0.01</xyz>
        <limit>
          <lower>-2.96706</lower>
          <upper>2.96706</upper>
          <effort>100</effort>
          <velocity>1.74533</velocity>
        </limit>
        <dynamics>
          <spring_reference>0</spring_reference>
          <spring_stiffness>0</spring_stiffness>
        </dynamics>
        <use_parent_model_frame>1</use_parent_model_frame>
      </axis>
    </joint>
    <link name='link_4'>
      <pose frame=''>0 0.0105 0.7405 0 -0 0</pose>
      <inertial>
        <pose frame=''>-0 -0.044916 0.067325 0 -0 0</pose>
        <mass>21.3976</mass>
        <inertia>
          <ixx>0.13383</ixx>
          <ixy>0</ixy>
          <ixz>-0</ixz>
          <iyy>0.127527</iyy>
          <iyz>-0.022269</iyz>
          <izz>0.047848</izz>
        </inertia>
      </inertial>
      <collision name='link_4_collision'>
        <pose frame=''>0 -0.0105 -0.7405 0 -0 0</pose>
        <geometry>
          <mesh>
            <scale>1 1 1</scale>
            <uri>model://iiwa7/meshes/link_4.stl</uri>
          </mesh>
        </geometry>
      </collision>
      <visual name='link_4_visual'>
        <pose frame=''>0 -0.0105 -0.7405 0 -0 0</pose>
        <geometry>
          <mesh>
            <scale>1 1 1</scale>
            <uri>model://iiwa7/meshes/link_4.stl</uri>
          </mesh>
        </geometry>
      </visual>
    </link>
    <joint name='A4' type='revolute'>
      <child>link_4</child>
      <parent>link_3</parent>
      <axis>
        <xyz>0 -0.01 0</xyz>
        <limit>
          <lower>-2.0944</lower>
          <upper>2.0944</upper>
          <effort>100</effort>
          <velocity>2.26893</velocity>
        </limit>
        <dynamics>
          <spring_reference>0</spring_reference>
          <spring_stiffness>0</spring_stiffness>
        </dynamics>
        <use_parent_model_frame>1</use_parent_model_frame>
      </axis>
    </joint>
    <link name='link_5'>
      <pose frame=''>0 0 0.915 0 -0 0</pose>
      <inertial>
        <pose frame=''>0 -0.021387 0.085469 0 -0 0</pose>
        <mass>13.2967</mass>
        <inertia>
          <ixx>0.079123</ixx>
          <ixy>-0</ixy>
          <ixz>-0</ixz>
          <iyy>0.068318</iyy>
          <iyz>0.024261</iyz>
          <izz>0.035085</izz>
        </inertia>
      </inertial>
      <collision name='link_5_collision'>
        <pose frame=''>0 0 -0.915 0 -0 0</pose>
        <geometry>
          <mesh>
            <scale>1 1 1</scale>
            <uri>model://iiwa7/meshes/link_5.stl</uri>
          </mesh>
        </geometry>
      </collision>
      <visual name='link_5_visual'>
        <pose frame=''>0 0 -0.915 0 -0 0</pose>
        <geometry>
          <mesh>
            <scale>1 1 1</scale>
            <uri>model://iiwa7/meshes/link_5.stl</uri>
          </mesh>
        </geometry>
      </visual>
    </link>
    <joint name='A5' type='revolute'>
      <child>link_5</child>
      <parent>link_4</parent>
      <axis>
        <xyz>0 0 0.01</xyz>
        <limit>
          <lower>-2.96706</lower>
          <upper>2.96706</upper>
          <effort>100</effort>
          <velocity>2.44346</velocity>
        </limit>
        <dynamics>
          <spring_reference>0</spring_reference>
          <spring_stiffness>0</spring_stiffness>
        </dynamics>
        <use_parent_model_frame>1</use_parent_model_frame>
      </axis>
    </joint>
    <link name='link_6'>
      <pose frame=''>0 -0.0707 1.1405 0 -0 0</pose>
      <inertial>
        <pose frame=''>-0 0.070987 0.002116 0 -0 0</pose>
        <mass>14.4215</mass>
        <inertia>
          <ixx>0.040001</ixx>
          <ixy>-0</ixy>
          <ixz>-0</ixz>
          <iyy>0.038461</iyy>
          <iyz>0.00196</iyz>
          <izz>0.027816</izz>
        </inertia>
      </inertial>
      <collision name='link_6_collision'>
        <pose frame=''>0 0.0707 -1.1405 0 -0 0</pose>
        <geometry>
          <mesh>
            <scale>1 1 1</scale>
            <uri>model://iiwa7/meshes/link_6.stl</uri>
          </mesh>
        </geometry>
      </collision>
      <visual name='link_6_visual'>
        <pose frame=''>0 0.0707 -1.1405 0 -0 0</pose>
        <geometry>
          <mesh>
            <scale>1 1 1</scale>
            <uri>model://iiwa7/meshes/link_6.stl</uri>
          </mesh>
        </geometry>
      </visual>
    </link>
    <joint name='A6' type='revolute'>
      <child>link_6</child>
      <parent>link_5</parent>
      <axis>
        <xyz>0 0.01 0</xyz>
        <limit>
          <lower>-2.0944</lower>
          <upper>2.0944</upper>
          <effort>100</effort>
          <velocity>3.14159</velocity>
        </limit>
        <dynamics>
          <spring_reference>0</spring_reference>
          <spring_stiffness>0</spring_stiffness>
        </dynamics>
        <use_parent_model_frame>1</use_parent_model_frame>
      </axis>
    </joint>
    <link name='link_7'>
      <pose frame=''>0 -0.0002 1.2314 0 -0 0</pose>
      <inertial>
        <pose frame=''>5e-06 -0 0.009883 0 -0 0</pose>
        <mass>2.11311</mass>
        <inertia>
          <ixx>0.001557</ixx>
          <ixy>-0</ixy>
          <ixz>-0</ixz>
          <iyy>0.00153</iyy>
          <iyz>0</iyz>
          <izz>0.002532</izz>
        </inertia>
      </inertial>
      <collision name='link_7_collision'>
        <pose frame=''>0 0.0002 -1.2314 0 -0 0</pose>
        <geometry>
          <mesh>
            <scale>1 1 1</scale>
            <uri>model://iiwa7/meshes/link_7.stl</uri>
          </mesh>
        </geometry>
      </collision>
      <visual name='link_7_visual'>
        <pose frame=''>0 0.0002 -1.2314 0 -0 0</pose>
        <geometry>
          <mesh>
            <scale>1 1 1</scale>
            <uri>model://iiwa7/meshes/link_7.stl</uri>
          </mesh>
        </geometry>
      </visual>
    </link>
    <joint name='A7' type='revolute'>
      <child>link_7</child>
      <parent>link_6</parent>
      <axis>
        <xyz>0 0 0.01</xyz>
        <limit>
          <lower>-3.05433</lower>
          <upper>3.05433</upper>
          <effort>100</effort>
          <velocity>3.14159</velocity>
        </limit>
        <dynamics>
          <spring_reference>0</spring_reference>
          <spring_stiffness>0</spring_stiffness>
        </dynamics>
        <use_parent_model_frame>1</use_parent_model_frame>
      </axis>
    </joint>
    <static>0</static>
    <plugin name='control' filename='libgazebo_ros_control.so'/>
  </model>
</sdf>
