<?xml version="1.0"?>

<robot xmlns:xacro="http://www.ros.org/wiki/xacro">

    <!-- some constants -->
    <xacro:property name="PI" value="3.1415926535897931" />
    <xacro:property name="joint_damping" value="10.0" />
    <xacro:property name="joint_friction" value="0.1" />
    <xacro:property name="joint_0_position_limit" value="170" />
    <xacro:property name="joint_1_position_limit" value="120" />
    <xacro:property name="joint_2_position_limit" value="170" />
    <xacro:property name="joint_3_position_limit" value="120" />
    <xacro:property name="joint_4_position_limit" value="170" />
    <xacro:property name="joint_5_position_limit" value="120" />
    <xacro:property name="joint_6_position_limit" value="175" />
    <xacro:property name="joint_0_velocity_limit" value="85" />
    <xacro:property name="joint_1_velocity_limit" value="85" />
    <xacro:property name="joint_2_velocity_limit" value="100" />
    <xacro:property name="joint_3_velocity_limit" value="75" />
    <xacro:property name="joint_4_velocity_limit" value="130" />
    <xacro:property name="joint_5_velocity_limit" value="135" />
    <xacro:property name="joint_6_velocity_limit" value="135" />
    <xacro:property name="effort_limit" value="200" />

    <!-- includes -->
    <xacro:include filename="$(find lbr_description)/gazebo/lbr.gazebo.xacro" />
    <xacro:include filename="$(find lbr_description)/ros2_control/lbr.ros2_control.xacro" />

    <!-- robot as extracted via https://github.com/syuntoku14/fusion2urdf -->
    <xacro:macro name="med14" params="base_frame:=^|world robot_name:=^|lbr sim:=^|true">

        <!--joint
        between {base_frame} and link_0-->
        <joint name="${base_frame}_joint" type="fixed">
            <parent link="${base_frame}" />
            <child link="link_0" />
        </joint>

        <link name="link_0">
            <inertial>
                <origin rpy="0 0 0"
                    xyz="-0.0018642104260720833 -9.120393625716289e-09 0.07751683665104403" />
                <mass value="8.146350" />
                <inertia ixx="0.044603" ixy="-0.000000" ixz="-0.000788" iyy="0.045465"
                    iyz="0.000000" izz="0.061903" />
            </inertial>
            <visual>
                <origin rpy="0 0 0" xyz="0 0 0" />
                <geometry>
                    <mesh filename="package://lbr_description/meshes/med14/visual/link_0.dae" />
                </geometry>
            </visual>
            <collision>
                <origin rpy="0 0 0" xyz="0 0 0" />
                <geometry>
                    <mesh filename="package://lbr_description/meshes/med14/collision/link_0.stl" />
                </geometry>
            </collision>
        </link>

        <joint name="A1" type="revolute">
            <origin rpy="0 0 0" xyz="0.0 0.0 0.147" />
            <parent link="link_0" />
            <child link="link_1" />
            <axis xyz="0.0 0.0 1.0" />
            <limit effort="${effort_limit}" lower="${-joint_0_position_limit * PI / 180}"
                upper="${joint_0_position_limit * PI / 180}"
                velocity="${joint_0_velocity_limit * PI / 180}" />
            <dynamics damping="${joint_damping}" friction="${joint_friction}" />
        </joint>

        <link name="link_1">
            <inertial>
                <origin rpy="0 0 0"
                    xyz="9.307232415315581e-08 -0.033795431550791004 0.13240370669453896" />
                <mass value="5.591386" />
                <inertia ixx="0.044885" ixy="-0.000000" ixz="-0.000000" iyy="0.045283"
                    iyz="0.006703" izz="0.016775" />
            </inertial>
            <visual>
                <origin rpy="0 0 0" xyz="-0.0 -0.0 -0.147" />
                <geometry>
                    <mesh filename="package://lbr_description/meshes/med14/visual/link_1.dae" />
                </geometry>
            </visual>
            <collision>
                <origin rpy="0 0 0" xyz="-0.0 -0.0 -0.147" />
                <geometry>
                    <mesh filename="package://lbr_description/meshes/med14/collision/link_1.stl" />
                </geometry>
            </collision>
        </link>

        <joint name="A2" type="revolute">
            <origin rpy="0 0 0" xyz="0.0 -0.01 0.2125" />
            <parent link="link_1" />
            <child link="link_2" />
            <axis xyz="0.0 1.0 0.0" />
            <limit effort="${effort_limit}" lower="${-joint_1_position_limit * PI / 180}"
                upper="${joint_1_position_limit * PI / 180}"
                velocity="${joint_1_velocity_limit * PI / 180}" />
            <dynamics damping="${joint_damping}" friction="${joint_friction}" />
        </joint>

        <link name="link_2">
            <inertial>
                <origin rpy="0 0 0"
                    xyz="0.0001358226533474577 0.0475476440926152 0.07632205850106144" />
                <mass value="6.013539" />
                <inertia ixx="0.058332" ixy="-0.000035" ixz="0.000059" iyy="0.057063" iyz="0.010606"
                    izz="0.017466" />
            </inertial>
            <visual>
                <origin rpy="0 0 0" xyz="-0.0 0.01 -0.3595" />
                <geometry>
                    <mesh filename="package://lbr_description/meshes/med14/visual/link_2.dae" />
                </geometry>
            </visual>
            <collision>
                <origin rpy="0 0 0" xyz="-0.0 0.01 -0.3595" />
                <geometry>
                    <mesh filename="package://lbr_description/meshes/med14/collision/link_2.stl" />
                </geometry>
            </collision>
        </link>

        <joint name="A3" type="revolute">
            <origin rpy="0 0 0" xyz="-0.0 0.01 0.228" />
            <parent link="link_2" />
            <child link="link_3" />
            <axis xyz="0.0 0.0 1.0" />
            <limit effort="${effort_limit}" lower="${-joint_2_position_limit * PI / 180}"
                upper="${joint_2_position_limit * PI / 180}"
                velocity="${joint_2_velocity_limit * PI / 180}" />
            <dynamics damping="${joint_damping}" friction="${joint_friction}" />
        </joint>

        <link name="link_3">
            <inertial>
                <origin rpy="0 0 0"
                    xyz="5.689213978259012e-08 0.03491265072974692 0.12310820658934007" />
                <mass value="3.658768" />
                <inertia ixx="0.022960" ixy="-0.000000" ixz="0.000000" iyy="0.021913"
                    iyz="-0.004065" izz="0.008140" />
            </inertial>
            <visual>
                <origin rpy="0 0 0" xyz="0.0 -0.0 -0.5875" />
                <geometry>
                    <mesh filename="package://lbr_description/meshes/med14/visual/link_3.dae" />
                </geometry>
            </visual>
            <collision>
                <origin rpy="0 0 0" xyz="0.0 -0.0 -0.5875" />
                <geometry>
                    <mesh filename="package://lbr_description/meshes/med14/collision/link_3.stl" />
                </geometry>
            </collision>
        </link>

        <joint name="A4" type="revolute">
            <origin rpy="0 0 0" xyz="0.0 0.0105 0.192" />
            <parent link="link_3" />
            <child link="link_4" />
            <axis xyz="0.0 -1.0 0.0" />
            <limit effort="${effort_limit}" lower="${-joint_3_position_limit * PI / 180}"
                upper="${joint_3_position_limit * PI / 180}"
                velocity="${joint_3_velocity_limit * PI / 180}" />
            <dynamics damping="${joint_damping}" friction="${joint_friction}" />
        </joint>

        <link name="link_4">
            <inertial>
                <origin rpy="0 0 0"
                    xyz="-3.025185496951432e-08 -0.03979329512420171 0.08694364647762443" />
                <mass value="4.358282" />
                <inertia ixx="0.034259" ixy="-0.000000" ixz="-0.000000" iyy="0.032514"
                    iyz="-0.006365" izz="0.010447" />
            </inertial>
            <visual>
                <origin rpy="0 0 0" xyz="0.0 -0.0105 -0.7795" />
                <geometry>
                    <mesh filename="package://lbr_description/meshes/med14/visual/link_4.dae" />
                </geometry>
            </visual>
            <collision>
                <origin rpy="0 0 0" xyz="0.0 -0.0105 -0.7795" />
                <geometry>
                    <mesh filename="package://lbr_description/meshes/med14/collision/link_4.stl" />
                </geometry>
            </collision>
        </link>

        <joint name="A5" type="revolute">
            <origin rpy="0 0 0" xyz="0.0 -0.0105 0.2075" />
            <parent link="link_4" />
            <child link="link_5" />
            <axis xyz="0.0 0.0 1.0" />
            <limit effort="${effort_limit}" lower="${-joint_4_position_limit * PI / 180}"
                upper="${joint_4_position_limit * PI / 180}"
                velocity="${joint_4_velocity_limit * PI / 180}" />
            <dynamics damping="${joint_damping}" friction="${joint_friction}" />
        </joint>

        <link name="link_5">
            <inertial>
                <origin rpy="0 0 0"
                    xyz="3.8871741664391765e-08 -0.029824284088761824 0.07626701716135809" />
                <mass value="1.652994" />
                <inertia ixx="0.009172" ixy="0.000000" ixz="-0.000000" iyy="0.007714" iyz="0.003033"
                    izz="0.004159" />
            </inertial>
            <visual>
                <origin rpy="0 0 0" xyz="-0.0 0.0 -0.987" />
                <geometry>
                    <mesh filename="package://lbr_description/meshes/med14/visual/link_5.dae" />
                </geometry>
            </visual>
            <collision>
                <origin rpy="0 0 0" xyz="-0.0 0.0 -0.987" />
                <geometry>
                    <mesh filename="package://lbr_description/meshes/med14/collision/link_5.stl" />
                </geometry>
            </collision>
        </link>

        <joint name="A6" type="revolute">
            <origin rpy="0 0 0" xyz="0.0 -0.0707 0.1925" />
            <parent link="link_5" />
            <child link="link_6" />
            <axis xyz="0.0 1.0 0.0" />
            <limit effort="${effort_limit}" lower="${-joint_5_position_limit * PI / 180}"
                upper="${joint_5_position_limit * PI / 180}"
                velocity="${joint_5_velocity_limit * PI / 180}" />
            <dynamics damping="${joint_damping}" friction="${joint_friction}" />
        </joint>

        <link name="link_6">
            <inertial>
                <origin rpy="0 0 0"
                    xyz="-7.073221484902805e-07 0.07101990943401978 0.004952526180380223" />
                <mass value="2.598208" />
                <inertia ixx="0.007640" ixy="-0.000000" ixz="0.000000" iyy="0.007355" iyz="0.000336"
                    izz="0.005004" />
            </inertial>
            <visual>
                <origin rpy="0 0 0" xyz="-0.0 0.0707 -1.1795" />
                <geometry>
                    <mesh filename="package://lbr_description/meshes/med14/visual/link_6.dae" />
                </geometry>
            </visual>
            <collision>
                <origin rpy="0 0 0" xyz="-0.0 0.0707 -1.1795" />
                <geometry>
                    <mesh filename="package://lbr_description/meshes/med14/collision/link_6.stl" />
                </geometry>
            </collision>
        </link>

        <joint name="A7" type="revolute">
            <origin rpy="0 0 0" xyz="0.0 0.0707 0.091" />
            <parent link="link_6" />
            <child link="link_7" />
            <axis xyz="0.0 0.0 1.0" />
            <limit effort="${effort_limit}" lower="${-joint_6_position_limit * PI / 180}"
                upper="${joint_6_position_limit * PI / 180}"
                velocity="${joint_6_velocity_limit * PI / 180}" />
            <dynamics damping="${joint_damping}" friction="${joint_friction}" />
        </joint>

        <link name="link_7">
            <inertial>
                <origin rpy="0 0 0"
                    xyz="3.121827460016089e-06 -1.635815563460264e-06 0.0137822955218736" />
                <mass value="0.280472" />
                <inertia ixx="0.000185" ixy="0.000000" ixz="-0.000000" iyy="0.000185" iyz="0.000000"
                    izz="0.000323" />
            </inertial>
            <visual>
                <origin rpy="0 0 0" xyz="-0.0 -0.0 -1.2705" />
                <geometry>
                    <mesh filename="package://lbr_description/meshes/med14/visual/link_7.dae" />
                </geometry>
            </visual>
            <collision>
                <origin rpy="0 0 0" xyz="-0.0 -0.0 -1.2705" />
                <geometry>
                    <mesh filename="package://lbr_description/meshes/med14/collision/link_7.stl" />
                </geometry>
            </collision>
        </link>

        <joint name="joint_ee" type="fixed">
            <parent link="link_7" />
            <child link="link_ee" />
            <origin xyz="0 0 0.035" rpy="0 0 0" />
        </joint>

        <link name="link_ee">
        </link>

        <xacro:lbr_gazebo robot_name="${robot_name}" />
        <!-- TODO: move modes to args, decouple urdf/gazebo/controls -->
        <xacro:lbr_hardware_interface
            joint_0_position_limit="${joint_0_position_limit * PI / 180}"
            joint_1_position_limit="${joint_1_position_limit * PI / 180}"
            joint_2_position_limit="${joint_2_position_limit * PI / 180}"
            joint_3_position_limit="${joint_3_position_limit * PI / 180}"
            joint_4_position_limit="${joint_4_position_limit * PI / 180}"
            joint_5_position_limit="${joint_5_position_limit * PI / 180}"
            joint_6_position_limit="${joint_6_position_limit * PI / 180}"
            effort_limit="${effort_limit}"
            sim="${sim}" remote_host="INADDR_ANY" port_id="30200"
            robot_name="${robot_name}" />

    </xacro:macro>
</robot>