<sdf version='1.6'>
  <model name='med14'>
    <link name='base_link'>
      <pose frame=''>0 0 0 0 -0 0</pose>
      <inertial>
        <pose frame=''>-0.001864 -0 0.077517 0 -0 0</pose>
        <mass>46.9902</mass>
        <inertia>
          <ixx>0.257284</ixx>
          <ixy>-0</ixy>
          <ixz>-0.004545</ixz>
          <iyy>0.262253</iyy>
          <iyz>0</iyz>
          <izz>0.357074</izz>
        </inertia>
      </inertial>
      <collision name='base_link_collision'>
        <pose frame=''>0 0 0 0 -0 0</pose>
        <geometry>
          <mesh>
            <scale>1 1 1</scale>
            <uri>model://fusion2urdf/lbr_description/meshes/med14/base_link.stl</uri>
          </mesh>
        </geometry>
      </collision>
      <visual name='base_link_visual'>
        <pose frame=''>0 0 0 0 -0 0</pose>
        <geometry>
          <mesh>
            <scale>1 1 1</scale>
            <uri>model://fusion2urdf/lbr_description/meshes/med14/base_link.stl</uri>
          </mesh>
        </geometry>
      </visual>
    </link>
    <joint name='world_iiwa7_joint' type='fixed'>
      <child>base_link</child>
      <parent>world</parent>
    </joint>
    <link name='link_1'>
      <pose frame=''>0 0 0.147 0 -0 0</pose>
      <inertial>
        <pose frame=''>0 -0.033795 0.132404 0 -0 0</pose>
        <mass>32.2525</mass>
        <inertia>
          <ixx>0.258906</ixx>
          <ixy>-0</ixy>
          <ixz>-0</ixz>
          <iyy>0.261201</iyy>
          <iyz>0.038666</iyz>
          <izz>0.096765</izz>
        </inertia>
      </inertial>
      <collision name='link_1_collision'>
        <pose frame=''>-0 -0 -0.147 0 -0 0</pose>
        <geometry>
          <mesh>
            <scale>1 1 1</scale>
            <uri>model://fusion2urdf/lbr_description/meshes/med14/link_1.stl</uri>
          </mesh>
        </geometry>
      </collision>
      <visual name='link_1_visual'>
        <pose frame=''>-0 -0 -0.147 0 -0 0</pose>
        <geometry>
          <mesh>
            <scale>1 1 1</scale>
            <uri>model://fusion2urdf/lbr_description/meshes/med14/link_1.stl</uri>
          </mesh>
        </geometry>
      </visual>
    </link>
    <joint name='A1' type='revolute'>
      <child>link_1</child>
      <parent>base_link</parent>
      <axis>
        <xyz>0 0 0.01</xyz>
        <limit>
          <lower>-2.96706</lower>
          <upper>2.96706</upper>
          <effort>100</effort>
          <velocity>1.48353</velocity>
        </limit>
        <dynamics>
          <spring_reference>0</spring_reference>
          <spring_stiffness>0</spring_stiffness>
        </dynamics>
        <use_parent_model_frame>1</use_parent_model_frame>
      </axis>
    </joint>
    <link name='link_2'>
      <pose frame=''>0 -0.01 0.3595 0 -0 0</pose>
      <inertial>
        <pose frame=''>0.000136 0.047548 0.076322 0 -0 0</pose>
        <mass>34.6876</mass>
        <inertia>
          <ixx>0.336472</ixx>
          <ixy>-0.0002</ixy>
          <ixz>0.000342</ixz>
          <iyy>0.329156</iyy>
          <iyz>0.06118</iyz>
          <izz>0.100748</izz>
        </inertia>
      </inertial>
      <collision name='link_2_collision'>
        <pose frame=''>-0 0.01 -0.3595 0 -0 0</pose>
        <geometry>
          <mesh>
            <scale>1 1 1</scale>
            <uri>model://fusion2urdf/lbr_description/meshes/med14/link_2.stl</uri>
          </mesh>
        </geometry>
      </collision>
      <visual name='link_2_visual'>
        <pose frame=''>-0 0.01 -0.3595 0 -0 0</pose>
        <geometry>
          <mesh>
            <scale>1 1 1</scale>
            <uri>model://fusion2urdf/lbr_description/meshes/med14/link_2.stl</uri>
          </mesh>
        </geometry>
      </visual>
    </link>
    <joint name='A2' type='revolute'>
      <child>link_2</child>
      <parent>link_1</parent>
      <axis>
        <xyz>0 0.01 0</xyz>
        <limit>
          <lower>-2.0944</lower>
          <upper>2.0944</upper>
          <effort>100</effort>
          <velocity>1.48353</velocity>
        </limit>
        <dynamics>
          <spring_reference>0</spring_reference>
          <spring_stiffness>0</spring_stiffness>
        </dynamics>
        <use_parent_model_frame>1</use_parent_model_frame>
      </axis>
    </joint>
    <link name='link_3'>
      <pose frame=''>0 0 0.5875 0 -0 0</pose>
      <inertial>
        <pose frame=''>0 0.034913 0.123108 0 -0 0</pose>
        <mass>21.1047</mass>
        <inertia>
          <ixx>0.132439</ixx>
          <ixy>-0</ixy>
          <ixz>0</ixz>
          <iyy>0.126397</iyy>
          <iyz>-0.023446</iyz>
          <izz>0.046954</izz>
        </inertia>
      </inertial>
      <collision name='link_3_collision'>
        <pose frame=''>0 -0 -0.5875 0 -0 0</pose>
        <geometry>
          <mesh>
            <scale>1 1 1</scale>
            <uri>model://fusion2urdf/lbr_description/meshes/med14/link_3.stl</uri>
          </mesh>
        </geometry>
      </collision>
      <visual name='link_3_visual'>
        <pose frame=''>0 -0 -0.5875 0 -0 0</pose>
        <geometry>
          <mesh>
            <scale>1 1 1</scale>
            <uri>model://fusion2urdf/lbr_description/meshes/med14/link_3.stl</uri>
          </mesh>
        </geometry>
      </visual>
    </link>
    <joint name='A3' type='revolute'>
      <child>link_3</child>
      <parent>link_2</parent>
      <axis>
        <xyz>0 0 0.01</xyz>
        <limit>
          <lower>-2.96706</lower>
          <upper>2.96706</upper>
          <effort>100</effort>
          <velocity>1.74533</velocity>
        </limit>
        <dynamics>
          <spring_reference>0</spring_reference>
          <spring_stiffness>0</spring_stiffness>
        </dynamics>
        <use_parent_model_frame>1</use_parent_model_frame>
      </axis>
    </joint>
    <link name='link_4'>
      <pose frame=''>0 0.0105 0.7795 0 -0 0</pose>
      <inertial>
        <pose frame=''>-0 -0.039793 0.086944 0 -0 0</pose>
        <mass>25.1396</mass>
        <inertia>
          <ixx>0.197617</ixx>
          <ixy>-0</ixy>
          <ixz>-0</ixz>
          <iyy>0.187546</iyy>
          <iyz>-0.036716</iyz>
          <izz>0.060263</izz>
        </inertia>
      </inertial>
      <collision name='link_4_collision'>
        <pose frame=''>0 -0.0105 -0.7795 0 -0 0</pose>
        <geometry>
          <mesh>
            <scale>1 1 1</scale>
            <uri>model://fusion2urdf/lbr_description/meshes/med14/link_4.stl</uri>
          </mesh>
        </geometry>
      </collision>
      <visual name='link_4_visual'>
        <pose frame=''>0 -0.0105 -0.7795 0 -0 0</pose>
        <geometry>
          <mesh>
            <scale>1 1 1</scale>
            <uri>model://fusion2urdf/lbr_description/meshes/med14/link_4.stl</uri>
          </mesh>
        </geometry>
      </visual>
    </link>
    <joint name='A4' type='revolute'>
      <child>link_4</child>
      <parent>link_3</parent>
      <axis>
        <xyz>0 -0.01 0</xyz>
        <limit>
          <lower>-2.0944</lower>
          <upper>2.0944</upper>
          <effort>100</effort>
          <velocity>1.309</velocity>
        </limit>
        <dynamics>
          <spring_reference>0</spring_reference>
          <spring_stiffness>0</spring_stiffness>
        </dynamics>
        <use_parent_model_frame>1</use_parent_model_frame>
      </axis>
    </joint>
    <link name='link_5'>
      <pose frame=''>0 0 0.987 0 -0 0</pose>
      <inertial>
        <pose frame=''>0 -0.029824 0.076267 0 -0 0</pose>
        <mass>9.53488</mass>
        <inertia>
          <ixx>0.052905</ixx>
          <ixy>0</ixy>
          <ixz>-0</ixz>
          <iyy>0.044495</iyy>
          <iyz>0.017493</iyz>
          <izz>0.023991</izz>
        </inertia>
      </inertial>
      <collision name='link_5_collision'>
        <pose frame=''>-0 0 -0.987 0 -0 0</pose>
        <geometry>
          <mesh>
            <scale>1 1 1</scale>
            <uri>model://fusion2urdf/lbr_description/meshes/med14/link_5.stl</uri>
          </mesh>
        </geometry>
      </collision>
      <visual name='link_5_visual'>
        <pose frame=''>-0 0 -0.987 0 -0 0</pose>
        <geometry>
          <mesh>
            <scale>1 1 1</scale>
            <uri>model://fusion2urdf/lbr_description/meshes/med14/link_5.stl</uri>
          </mesh>
        </geometry>
      </visual>
    </link>
    <joint name='A5' type='revolute'>
      <child>link_5</child>
      <parent>link_4</parent>
      <axis>
        <xyz>0 0 0.01</xyz>
        <limit>
          <lower>-2.96706</lower>
          <upper>2.96706</upper>
          <effort>100</effort>
          <velocity>2.26893</velocity>
        </limit>
        <dynamics>
          <spring_reference>0</spring_reference>
          <spring_stiffness>0</spring_stiffness>
        </dynamics>
        <use_parent_model_frame>1</use_parent_model_frame>
      </axis>
    </joint>
    <link name='link_6'>
      <pose frame=''>0 -0.0707 1.1795 0 -0 0</pose>
      <inertial>
        <pose frame=''>-1e-06 0.07102 0.004953 0 -0 0</pose>
        <mass>14.9871</mass>
        <inertia>
          <ixx>0.044068</ixx>
          <ixy>-0</ixy>
          <ixz>1e-06</ixz>
          <iyy>0.042427</iyy>
          <iyz>0.001941</iyz>
          <izz>0.028865</izz>
        </inertia>
      </inertial>
      <collision name='link_6_collision'>
        <pose frame=''>-0 0.0707 -1.1795 0 -0 0</pose>
        <geometry>
          <mesh>
            <scale>1 1 1</scale>
            <uri>model://fusion2urdf/lbr_description/meshes/med14/link_6.stl</uri>
          </mesh>
        </geometry>
      </collision>
      <visual name='link_6_visual'>
        <pose frame=''>-0 0.0707 -1.1795 0 -0 0</pose>
        <geometry>
          <mesh>
            <scale>1 1 1</scale>
            <uri>model://fusion2urdf/lbr_description/meshes/med14/link_6.stl</uri>
          </mesh>
        </geometry>
      </visual>
    </link>
    <joint name='A6' type='revolute'>
      <child>link_6</child>
      <parent>link_5</parent>
      <axis>
        <xyz>0 0.01 0</xyz>
        <limit>
          <lower>-2.0944</lower>
          <upper>2.0944</upper>
          <effort>100</effort>
          <velocity>2.35619</velocity>
        </limit>
        <dynamics>
          <spring_reference>0</spring_reference>
          <spring_stiffness>0</spring_stiffness>
        </dynamics>
        <use_parent_model_frame>1</use_parent_model_frame>
      </axis>
    </joint>
    <link name='link_7'>
      <pose frame=''>0 0 1.2705 0 -0 0</pose>
      <inertial>
        <pose frame=''>3e-06 -2e-06 0.013782 0 -0 0</pose>
        <mass>1.61783</mass>
        <inertia>
          <ixx>0.001066</ixx>
          <ixy>0</ixy>
          <ixz>-0</ixz>
          <iyy>0.001066</iyy>
          <iyz>0</iyz>
          <izz>0.001864</izz>
        </inertia>
      </inertial>
      <collision name='link_7_collision'>
        <pose frame=''>-0 -0 -1.2705 0 -0 0</pose>
        <geometry>
          <mesh>
            <scale>1 1 1</scale>
            <uri>model://fusion2urdf/lbr_description/meshes/med14/link_7.stl</uri>
          </mesh>
        </geometry>
      </collision>
      <visual name='link_7_visual'>
        <pose frame=''>-0 -0 -1.2705 0 -0 0</pose>
        <geometry>
          <mesh>
            <scale>1 1 1</scale>
            <uri>model://fusion2urdf/lbr_description/meshes/med14/link_7.stl</uri>
          </mesh>
        </geometry>
      </visual>
    </link>
    <joint name='A7' type='revolute'>
      <child>link_7</child>
      <parent>link_6</parent>
      <axis>
        <xyz>0 0 0.01</xyz>
        <limit>
          <lower>-3.05433</lower>
          <upper>3.05433</upper>
          <effort>100</effort>
          <velocity>2.35619</velocity>
        </limit>
        <dynamics>
          <spring_reference>0</spring_reference>
          <spring_stiffness>0</spring_stiffness>
        </dynamics>
        <use_parent_model_frame>1</use_parent_model_frame>
      </axis>
    </joint>
    <static>0</static>
    <plugin name='control' filename='libgazebo_ros_control.so'/>
  </model>
</sdf>
